Workbook

Sheet Code
A1: HUNGARY 2008-2009
A4: Code | B4: Economic activities
A5: A01 | B5: Agriculture and hunting
A6: A02 | B6: Forestry and logging
A7: A03 | B7: Fishing and aquaculture
A8: B05 | B8: Mining of coal and lignite
A9: B06 | B9: Extraction of crude petroleum and natural gas
A10: B07 | B10: Mining of metal ores
A11: B08 | B11: Other mining and quarrying
A12: B09 | B12: Mining support service activities
A13: C10T12 | B13: Manufacture of food products; beverages and tobacco products
A14: C13T15 | B14: Manufacture of textiles, wearing apparel, leather and related products
A15: C16 | B15: Manufacture of wood and of products of wood and cork
... A54: T | B54: Activities of households as employers; undifferentiated goods- and services-producing activities of households for own use

Sheet HUNGARY2008ttl
B1: A01_02 | C1: A03 | D1: B05_06 | E1: B07_08 | F1: B09 | G1: C10T12 | H1: C13T15 | I1: C16 | J1: C17_18 | K1: C19 | L1: C20 | M1: C21 | N1: C22 | O1: C23 | P1: C24 | Q1: C25 | R1: C26 | S1: C27 | T1: C28 | U1: C29 | V1: C30 | W1: C31T33 | X1: D | Y1: E | Z1: F | AA1: G | AB1: H49 | AC1: H50 | AD1: H51 | AE1: H52 | AF1: H53 | AG1: I | AH1: J58T60 | AI1: J61 | AJ1: J62_63 | AK1: K | AL1: L | AM1: M | AN1: N | AO1: O | AP1: P | AQ1: Q | AR1: R | AS1: S | AT1: T | AU1: HFCE | AV1: NPISH | AW1: GGFC | AX1: GFCF | AY1: INVNT | AZ1: DPABR | BA1: CONS_NONRES | BB1: EXPO | BC1: IMPO | BD1: Final Demand(F) | BE1: output(X)
A2: TTL_A01_02 | B2: 2817 | C2: 5.1 | D2: 0.6 | E2: 0.6 | F2: 0.2 | G2: 4082.4 | H2: 15.3 | I2: 103.6 | J2: 10.7 | K2: 17.9 | L2: 18.6 | M2: 19.7 | N2: 46.6 | O2: 10.6 | P2: 8.1 | Q2: 9.9 | R2: 18.9 | S2: 14.3 | T2: 9.1 | U2: 30.5 | V2: 1.1 | W2: 18.6 | X2: 112.3 | Y2: 9 | Z2: 42.2 | AA2: 413.1 | AB2: 17.6 | AC2: 0.7 | AD2: 3.7 | AE2: 15.7 | AF2: 0.5 | AG2: 118.7 | AH2: 8.5 | AI2: 6.8 | AJ2: 2.5 | AK2: 6.1 | AL2: 18.2 | AM2: 28.7 | AN2: 21.3 | AO2: 13.6 | AP2: 5.1 | AQ2: 27.4 | AR2: 5.7 | AS2: 15 | AT2: 0 | AU2: 2531.1 | AV2: 0.4 | AW2: 25 | AX2: 422.7 | AY2: 151.6 | AZ2: 18.4 | BA2: 70.7 | BB2: 3274.3 | BC2: -927.3 | BD2: =SUM(AU2:BC2) -> 5566.9 | BE2: =SUM(B2:BC2) -> 13718.7
A3: TTL_A03 | B3: 1.8 | C3: 7.2 | D3: 0 | E3: 0 | F3: 0 | G3: 2.7 | H3: 0 | I3: 0 | J3: 0 | K3: 0.1 | L3: 0 | M3: 0 | N3: 0 | O3: 0 | P3: 0 | Q3: 0 | R3: 0.1 | S3: 0 | T3: 0 | U3: 0.2 | V3: 0 | W3: 0 | X3: 0.1 | Y3: 0 | Z3: 0.2 | AA3: 0.4 | AB3: 0 | AC3: 0 | AD3: 0 | AE3: 0.1 | AF3: 0 | AG3: 12.7 | AH3: 0 | AI3: 0 | AJ3: 0 | AK3: 0 | AL3: 0.1 | AM3: 0.1 | AN3: 0.1 | AO3: 0 | AP3: 0 | AQ3: 0.1 | AR3: 0.4 | AS3: 0.1 | AT3: 0 | AU3: 28.9 | AV3: 0.5 | AW3: 0.9 | AX3: 1.7 | AY3: 0.6 | AZ3: 1.1 | BA3: 4.6 | BB3: 3.1 | BC3: -7.2 | BD3: =SUM(AU3:BC3) -> 34.2 | BE3: =SUM(B3:BC3) -> 60.7 | BI3: Bottom 5 Industries
A4: TTL_B05_06 | B4: 39.1 | C4: 0.1 | D4: 15.3 | E4: 11.6 | F4: 0.6 | G4: 51.5 | H4: 2.2 | I4: 2.1 | J4: 9.4 | K4: 2216.9 | L4: 132.4 | M4: 10.9 | N4: 2.8 | O4: 60.4 | P4: 168.9 | Q4: 4.8 | R4: 5.2 | S4: 3.5 | T4: 3.6 | U4: 12.9 | V4: 2.7 | W4: 1.4 | X4: 1042 | Y4: 11.4 | Z4: 44.3 | AA4: 72 | AB4: 52 | AC4: 0.4 | AD4: 1.8 | AE4: 43.9 | AF4: 2.4 | AG4: 33.4 | AH4: 2.5 | AI4: 4.9 | AJ4: 1.5 | AK4: 6.6 | AL4: 24 | AM4: 36.9 | AN4: 15.3 | AO4: 50.8 | AP4: 50.7 | AQ4: 63 | AR4: 29.3 | AS4: 9.1 | AT4: 0 | AU4: 622.1 | AV4: 0 | AW4: 2.2 | AX4: 55.8 | AY4: 59.2 | AZ4: 0.6 | BA4: 1 | BB4: 52.5 | BC4: -4895.3 | BD4: =SUM(AU4:BC4) -> -4101.9 | BE4: =SUM(B4:BC4) -> 254.6
A5: TTL_B07_08 | B5: 21 | C5: 0 | D5: 27.1 | E5: 17.3 | F5: 7.9 | G5: 51.3 | H5: 1.2 | I5: 1.6 | J5: 5 | K5: 1 | L5: 14.4 | M5: 1.7 | N5: 8.4 | O5: 136.7 | P5: 31.2 | Q5: 20.8 | R5: 6.2 | S5: 10.4 | T5: 7.9 | U5: 16.5 | V5: 0.5 | W5: 3.6 | X5: 2.1 | Y5: 5.6 | Z5: 142 | AA5: 33.6 | AB5: 1.3 | AC5: 0.2 | AD5: 0 | AE5: 1.9 | AF5: 0 | AG5: 0.4 | AH5: 0.4 | AI5: 0.2 | AJ5: 1.3 | AK5: 0.2 | AL5: 51.9 | AM5: 9.5 | AN5: 2.6 | AO5: 2 | AP5: 2 | AQ5: 5.2 | AR5: 2.1 | AS5: 5.7 | AT5: 0 | AU5: 71.5 | AV5: 0 | AW5: 2.3 | AX5: 36.8 | AY5: 8.9 | AZ5: 0.2 | BA5: 0.8 | BB5: 49.6 | BC5: -436.1 | BD5: =SUM(AU5:BC5) -> -266 | BE5: =SUM(B5:BC5) -> 395.9 | BI5: Top 5 Industries
A6: TTL_B09 | B6: 0.4 | C6: 0 | D6: 38 | E6: 0.6 | F6: 9.2 | G6: 0.5 | H6: 0 | I6: 0.2 | J6: 0.1 | K6: 46.9 | L6: 1 | M6: 0.1 | N6: 0.7 | O6: 0.5 | P6: 2.9 | Q6: 0.1 | R6: 0.5 | S6: 0.2 | T6: 0.4 | U6: 1.8 | V6: 0.1 | W6: 0.5 | X6: 8 | Y6: 0.2 | Z6: 6.1 | AA6: 1.2 | AB6: 0.5 | AC6: 0 | AD6: 0 | AE6: 0.4 | AF6: 0 | AG6: 0.3 | AH6: 0.1 | AI6: 0.1 | AJ6: 0.1 | AK6: 0.2 | AL6: 0.5 | AM6: 0.8 | AN6: 0.3 | AO6: 0.4 | AP6: 0.3 | AQ6: 0.7 | AR6: 0.3 | AS6: 0.1 | AT6: 0 | AU6: 3.4 | AV6: 0 | AW6: 0.1 | AX6: 31.4 | AY6: 0.5 | AZ6: 0.1 | BA6: 0 | BB6: 54.3 | BC6: -29.7 | BD6: =SUM(AU6:BC6) -> 60.1 | BE6: =SUM(B6:BC6) -> 185.4
A7: TTL_C10T12 | B7: 954.6 | C7: 2.9 | D7: 1 | E7: 0.3 | F7: 0.1 | G7: 1373.7 | H7: 5 | I7: 2.2 | J7: 17.3 | K7: 43.4 | L7: 26.2 | M7: 17.3 | N7: 15.5 | O7: 5.7 | P7: 4.7 | Q7: 6.3 | R7: 17.5 | S7: 10.2 | T7: 4.8 | U7: 18.2 | V7: 0.7 | W7: 5.5 | X7: 26.3 | Y7: 3.1 | Z7: 16.2 | AA7: 226 | AB7: 6.7 | AC7: 2.3 | AD7: 4.9 | AE7: 2 | AF7: 0.6 | AG7: 1300.4 | AH7: 2.2 | AI7: 1.8 | AJ7: 1.7 | AK7: 4.9 | AL7: 18 | AM7: 26.2 | AN7: 49.3 | AO7: 30.5 | AP7: 5.7 | AQ7: 131.9 | AR7: 11.6 | AS7: 14.1 | AT7: 0 | AU7: 9433.5 | AV7: 7.3 | AW7: 12.8 | AX7: 27 | AY7: 200 | AZ7: 71.5 | BA7: 202.6 | BB7: 3094.8 | BC7: -2892.3 | BD7: =SUM(AU7:BC7) -> 10157.2 | BE7: =SUM(B7:BC7) -> 14576.7
A8: TTL_C13T15 | B8: 6.4 | C8: 0.1 | D8: 0.2 | E8: 0.3 | F8: 0.1 | G8: 12.5 | H8: 468.7 | I8: 1.7 | J8: 8.6 | K8: 2.2 | L8: 4.6 | M8: 3.5 | N8: 50.1 | O8: 5.9 | P8: 3.4 | Q8: 4.4 | R8: 20.8 | S8: 13.3 | T8: 11.2 | U8: 117.3 | V8: 0.8 | W8: 72.3 | X8: 3.7 | Y8: 4 | Z8: 18.1 | AA8: 40.5 | AB8: 4.4 | AC8: 0.2 | AD8: 0.6 | AE8: 2.4 | AF8: 1.3 | AG8: 7.9 | AH8: 1.2 | AI8: 1.9 | AJ8: 1.4 | AK8: 2.4 | AL8: 5.4 | AM8: 5.8 | AN8: 9.7 | AO8: 9.9 | AP8: 2.3 | AQ8: 18.9 | AR8: 6.6 | AS8: 22.7 | AT8: 0 | AU8: 1170.9 | AV8: 0 | AW8: 7 | AX8: 25.8 | AY8: 34.8 | AZ8: 34.8 | BA8: 75.1 | BB8: 1105.2 | BC8: -1202.9 | BD8: =SUM(AU8:BC8) -> 1250.7 | BE8: =SUM(B8:BC8) -> 2230.4
A9: TTL_C16 | B9: 29.5 | C9: 0.1 | D9: 0.1 | E9: 0.2 | F9: 0 | G9: 27.3 | H9: 5.7 | I9: 312.5 | J9: 7 | K9: 2.2 | L9: 16 | M9: 1.6 | N9: 18.2 | O9: 33.4 | P9: 10.1 | Q9: 30 | R9: 23.1 | S9: 23.4 | T9: 15.8 | U9: 46.1 | V9: 2.7 | W9: 177.4 | X9: 22.1 | Y9: 2.8 | Z9: 366.8 | AA9: 84.1 | AB9: 11.4 | AC9: 0.5 | AD9: 0.6 | AE9: 2.2 | AF9: 0.3 | AG9: 6 | AH9: 0.8 | AI9: 2.8 | AJ9: 0.4 | AK9: 1.2 | AL9: 72.4 | AM9: 20.9 | AN9: 10.3 | AO9: 3.3 | AP9: 0.7 | AQ9: 3.4 | AR9: 1.6 | AS9: 6 | AT9: 0 | AU9: 60.3 | AV9: 0 | AW9: 3 | AX9: 44.5 | AY9: 22.4 | AZ9: 3.8 | BA9: 7.1 | BB9: 594.5 | BC9: -630.1 | BD9: =SUM(AU9:BC9) -> 105.5 | BE9: =SUM(B9:BC9) -> 1508.5
A10: TTL_C17_18 | B10: 29.8 | C10: 0.1 | D10: 0.1 | E10: 0.5 | F10: 0 | G10: 311.5 | H10: 13.5 | I10: 30 | J10: 940.4 | K10: 3.7 | L10: 48.8 | M10: 25.7 | N10: 62.1 | O10: 25.9 | P10: 6.3 | Q10: 15.8 | R10: 78.1 | S10: 82.1 | T10: 14.6 | U10: 38.1 | V10: 1.5 | W10: 31.9 | X10: 17.2 | Y10: 4 | Z10: 17.1 | AA10: 432.9 | AB10: 14.1 | AC10: 0.2 | AD10: 1.1 | AE10: 13.4 | AF10: 7.7 | AG10: 15 | AH10: 348.6 | AI10: 7.5 | AJ10: 13.4 | AK10: 109.3 | AL10: 69.4 | AM10: 70.6 | AN10: 48.6 | AO10: 91.3 | AP10: 27.5 | AQ10: 14.7 | AR10: 13.3 | AS10: 16.8 | AT10: 0 | AU10: 407.1 | AV10: 0 | AW10: 4.8 | AX10: 22.7 | AY10: 43.4 | AZ10: 9.2 | BA10: 18.1 | BB10: 739.5 | BC10: -1389.2 | BD10: =SUM(AU10:BC10) -> -144.4 | BE10: =SUM(B10:BC10) -> 2969.8
A11: TTL_C19 | B11: 447 | C11: 2.4 | D11: 8.1 | E11: 16.2 | F11: 6.1 | G11: 153.8 | H11: 13.7 | I11: 15.8 | J11: 20.9 | K11: 899 | L11: 858.9 | M11: 37.5 | N11: 83.4 | O11: 121.8 | P11: 201.3 | Q11: 33.2 | R11: 61.1 | S11: 51.3 | T11: 30.2 | U11: 77.6 | V11: 4.3 | W11: 24.8 | X11: 319.9 | Y11: 67.8 | Z11: 372.9 | AA11: 550.4 | AB11: 1165.4 | AC11: 46.1 | AD11: 253.5 | AE11: 174.8 | AF11: 12.1 | AG11: 35.3 | AH11: 8.6 | AI11: 13.3 | AJ11: 14.4 | AK11: 52 | AL11: 100 | AM11: 99.5 | AN11: 94.2 | AO11: 91.8 | AP11: 40.6 | AQ11: 74.4 | AR11: 32.2 | AS11: 31 | AT11: 0 | AU11: 2877.3 | AV11: 0.1 | AW11: 18.5 | AX11: 97.9 | AY11: 112.1 | AZ11: 28.5 | BA11: 76.4 | BB11: 1918.8 | BC11: -2330 | BD11: =SUM(AU11:BC11) -> 2799.6 | BE11: =SUM(B11:BC11) -> 9618.2
A12: TTL_C20 | B12: 742.5 | C12: 0.1 | D12: 1.2 | E12: 5.3 | F12: 3 | G12: 384.9 | H12: 58.6 | I12: 45.4 | J12: 62.6 | K12: 335.2 | L12: 909.8 | M12: 283.8 | N12: 988.7 | O12: 201.5 | P12: 43.3 | Q12: 58.6 | R12: 171 | S12: 302.4 | T12: 46.6 | U12: 183.7 | V12: 6.1 | W12: 60.9 | X12: 67.4 | Y12: 31.1 | Z12: 188 | AA12: 245.3 | AB12: 38.3 | AC12: 2.1 | AD12: 4.2 | AE12: 14.2 | AF12: 2.8 | AG12: 33.5 | AH12: 10.1 | AI12: 2.4 | AJ12: 4.6 | AK12: 14.3 | AL12: 66.4 | AM12: 73.4 | AN12: 58.6 | AO12: 22.8 | AP12: 27 | AQ12: 168 | AR12: 32.4 | AS12: 44.8 | AT12: 0 | AU12: 706.9 | AV12: 0 | AW12: 17.5 | AX12: 38.3 | AY12: 102.1 | AZ12: 9.1 | BA12: 14.8 | BB12: 3106.3 | BC12: -4580.4 | BD12: =SUM(AU12:BC12) -> -585.4 | BE12: =SUM(B12:BC12) -> 5461.5
A13: TTL_C21 | B13: 54.7 | C13: 0.1 | D13: 0.2 | E13: 0.3 | F13: 0.2 | G13: 38.1 | H13: 4.1 | I13: 2.2 | J13: 3.5 | K13: 13.4 | L13: 35.7 | M13: 228.1 | N13: 36.1 | O13: 8.3 | P13: 8.5 | Q13: 4.1 | R13: 24.5 | S13: 15.9 | T13: 4.4 | U13: 27.7 | V13: 0.5 | W13: 4.3 | X13: 5.5 | Y13: 2 | Z13: 14 | AA13: 29.2 | AB13: 5 | AC13: 0.4 | AD13: 1.4 | AE13: 1.8 | AF13: 0.3 | AG13: 4.8 | AH13: 1.8 | AI13: 1.5 | AJ13: 2 | AK13: 3.3 | AL13: 6.2 | AM13: 15.8 | AN13: 6.2 | AO13: 5.7 | AP13: 3 | AQ13: 395.6 | AR13: 4.8 | AS13: 4.7 | AT13: 0 | AU13: 816.4 | AV13: 1.4 | AW13: 1268.6 | AX13: 49.5 | AY13: 47.5 | AZ13: 5.9 | BA13: 13 | BB13: 1864.4 | BC13: -1574.1 | BD13: =SUM(AU13:BC13) -> 2492.6 | BE13: =SUM(B13:BC13) -> 3522.5
A14: TTL_C22 | B14: 65.2 | C14: 0.3 | D14: 0.5 | E14: 0.9 | F14: 0.6 | G14: 299.5 | H14: 70.7 | I14: 50 | J14: 64.4 | K14: 8.7 | L14: 98.5 | M14: 43.9 | N14: 610.7 | O14: 47.7 | P14: 12.7 | Q14: 61.7 | R14: 909.3 | S14: 320.2 | T14: 75.3 | U14: 773.5 | V14: 8.8 | W14: 142.4 | X14: 20.7 | Y14: 41.6 | Z14: 395.8 | AA14: 132.7 | AB14: 70.4 | AC14: 0.4 | AD14: 0.9 | AE14: 18.8 | AF14: 1.8 | AG14: 11.3 | AH14: 4.8 | AI14: 3.7 | AJ14: 1.3 | AK14: 22.6 | AL14: 49.6 | AM14: 41.9 | AN14: 25.1 | AO14: 29.2 | AP14: 2.6 | AQ14: 49.1 | AR14: 4.9 | AS14: 4.8 | AT14: 0 | AU14: 407 | AV14: 0 | AW14: 9.7 | AX14: 85.5 | AY14: 80.1 | AZ14: 1.3 | BA14: 9.1 | BB14: 2894.6 | BC14: -2845.5 | BD14: =SUM(AU14:BC14) -> 641.8 | BE14: =SUM(B14:BC14) -> 5241.3
A15: TTL_C23 | B15: 33.8 | C15: 0.2 | D15: 0.2 | E15: 8.1 | F15: 1.6 | G15: 107.6 | H15: 6.2 | I15: 12.2 | J15: 3.2 | K15: 6.1 | L15: 15.2 | M15: 15.1 | N15: 25.3 | O15: 524.7 | P15: 18.1 | Q15: 14.1 | R15: 64.2 | S15: 77.9 | T15: 25.2 | U15: 207.8 | V15: 2.8 | W15: 16.3 | X15: 32.8 | Y15: 12.6 | Z15: 1553.7 | AA15: 112.1 | AB15: 8.5 | AC15: 1.9 | AD15: 1 | AE15: 14 | AF15: 0.3 | AG15: 9.8 | AH15: 0.8 | AI15: 6.1 | AJ15: 1.2 | AK15: 3.3 | AL15: 308 | AM15: 34.1 | AN15: 13.2 | AO15: 8.1 | AP15: 2.6 | AQ15: 17.4 | AR15: 1.9 | AS15: 2.7 | AT15: 0 | AU15: 162.9 | AV15: 0 | AW15: 6.6 | AX15: 334.7 | AY15: 47.9 | AZ15: 1 | BA15: 2.2 | BB15: 1332 | BC15: -1045.1 | BD15: =SUM(AU15:BC15) -> 842.2 | BE15: =SUM(B15:BC15) -> 4174.2
A16: TTL_C24 | B16: 26.9 | C16: 0.1 | D16: 4.9 | E16: 7.2 | F16: 13 | G16: 39.9 | H16: 3.6 | I16: 50.4 | J16: 6.9 | K16: 30.4 | L16: 44.9 | M16: 15 | N16: 95 | O16: 101.5 | P16: 1543.6 | Q16: 1349.5 | R16: 129.1 | S16: 1008.4 | T16: 488.5 | U16: 629 | V16: 60.9 | W16: 119.9 | X16: 36.8 | Y16: 29.5 | Z16: 724.8 | AA16: 143.6 | AB16: 157.4 | AC16: 0.9 | AD16: 0.1 | AE16: 12.1 | AF16: 0 | AG16: 0.8 | AH16: 0.3 | AI16: 0.5 | AJ16: 1.1 | AK16: 0.3 | AL16: 84.3 | AM16: 109.9 | AN16: 136.3 | AO16: 0.1 | AP16: 0.3 | AQ16: 2.4 | AR16: 0.5 | AS16: 7.2 | AT16: 0 | AU16: 3.1 | AV16: 0 | AW16: 0.1 | AX16: 4 | AY16: 115.1 | AZ16: 0.1 | BA16: 0 | BB16: 2466.5 | BC16: -5041.1 | BD16: =SUM(AU16:BC16) -> -2452.2 | BE16: =SUM(B16:BC16) -> 4765.6
A17: TTL_C25 | B17: 31.2 | C17: 0.2 | D17: 0.5 | E17: 1.5 | F17: 1 | G17: 277.3 | H17: 24.1 | I17: 39.2 | J17: 17.6 | K17: 26.4 | L17: 33.5 | M17: 14.9 | N17: 162.6 | O17: 32.7 | P17: 86.3 | Q17: 929 | R17: 347.8 | S17: 302 | T17: 594.7 | U17: 1148.6 | V17: 24.5 | W17: 142.8 | X17: 86.8 | Y17: 22.3 | Z17: 835.1 | AA17: 186.9 | AB17: 33.4 | AC17: 0.7 | AD17: 2.4 | AE17: 31.3 | AF17: 1.3 | AG17: 11.4 | AH17: 3.6 | AI17: 21.6 | AJ17: 8 | AK17: 9.1 | AL17: 89 | AM17: 32.3 | AN17: 24.8 | AO17: 22.6 | AP17: 20.9 | AQ17: 24.7 | AR17: 13.5 | AS17: 8.7 | AT17: 0 | AU17: 376.5 | AV17: 0 | AW17: 9.8 | AX17: 670.5 | AY17: 83 | AZ17: 2.5 | BA17: 5.8 | BB17: 2247.5 | BC17: -3027.1 | BD17: =SUM(AU17:BC17) -> 368.5 | BE17: =SUM(B17:BC17) -> 6097.3
... A46: TTL_T | B46: 0 | C46: 0 | D46: 0 | E46: 0 | F46: 0 | G46: 0 | H46: 0 | I46: 0 | J46: 0 | K46: 0 | L46: 0 | M46: 0 | N46: 0 | O46: 0 | P46: 0 | Q46: 0 | R46: 0 | S46: 0 | T46: 0 | U46: 0 | V46: 0 | W46: 0 | X46: 0 | Y46: 0 | Z46: 0 | AA46: 0 | AB46: 0 | AC46: 0 | AD46: 0 | AE46: 0 | AF46: 0 | AG46: 0 | AH46: 0 | AI46: 0 | AJ46: 0 | AK46: 0 | AL46: 0 | AM46: 0 | AN46: 0 | AO46: 0 | AP46: 0 | AQ46: 0 | AR46: 0 | AS46: 0 | AT46: 0 | AU46: 18.1 | AV46: 0 | AW46: 0 | AX46: 0 | AY46: 0 | AZ46: 0 | BA46: 0 | BB46: 0 | BC46: 0 | BD46: =SUM(AU46:BC46) -> 18.1 | BE46: =SUM(B46:BC46) -> 18.1
A47: TXS_IMP_FNL | B47: 99.7 | C47: 0.4 | D47: 4.8 | E47: 9.4 | F47: 1.1 | G47: 98.2 | H47: 98.5 | I47: 8.7 | J47: 25.1 | K47: 1513 | L47: 180.1 | M47: 25.6 | N47: 57.8 | O47: 60.5 | P47: 142.1 | Q47: 25 | R47: 294.8 | S47: 59.1 | T47: 29.6 | U47: 240.3 | V47: 11.5 | W47: 37.1 | X47: 718.7 | Y47: 16.8 | Z47: 105.8 | AA47: 128.9 | AB47: 125.5 | AC47: 3.7 | AD47: 19.2 | AE47: 45.5 | AF47: 3.1 | AG47: 52.3 | AH47: 6 | AI47: 7.7 | AJ47: 4 | AK47: 9.8 | AL47: 33.5 | AM47: 40.5 | AN47: 24.7 | AO47: 41.8 | AP47: 36.5 | AQ47: 0 | AR47: 0 | AS47: 0 | AT47: 0 | AU47: 0 | AV47: 0 | AW47: 0 | AX47: 0 | AY47: 0 | AZ47: 179.2 | BA47: 0 | BB47: 0 | BC47: -4625.7
A48: TXS_INT_FNL | B48: 220.8 | C48: 1.7 | D48: 2.3 | E48: 6.1 | F48: 2.1 | G48: 189.5 | H48: 21.1 | I48: 21.3 | J48: 45.3 | K48: 48.6 | L48: 250.4 | M48: 42.9 | N48: 61.4 | O48: 71.4 | P48: 50.3 | Q48: 47.5 | R48: 159.8 | S48: 75 | T48: 40.6 | U48: 190.7 | V48: 12.6 | W48: 42.5 | X48: 125 | Y48: 64.8 | Z48: 254.1 | AA48: 582.1 | AB48: 358.8 | AC48: 12 | AD48: 72.4 | AE48: 100.1 | AF48: 11.9 | AG48: 105 | AH48: 46.3 | AI48: 68 | AJ48: 44.1 | AK48: 135.2 | AL48: 165.6 | AM48: 177.8 | AN48: 98.7 | AO48: 152.3 | AP48: 62.5 | AQ48: 103.4 | AR48: 62.6 | AS48: 47.7 | AT48: 0 | AU48: 11051.5 | AV48: 21 | AW48: 365.3 | AX48: 2109.7 | AY48: 271.9 | AZ48: 0 | BA48: 420.1 | BB48: 3876.4 | BC48: 0
A49: TTL_INT_FNL | B49: 8238 | C49: 38.6 | D49: 181.5 | E49: 221.7 | F49: 102.5 | G49: 11710.7 | H49: 1480.8 | I49: 1065.8 | J49: 2089 | K49: 7415.1 | L49: 4378 | M49: 1800.4 | N49: 3915.2 | O49: 2770.8 | P49: 3710.6 | Q49: 3972.8 | R49: 20292.9 | S49: 5597.4 | T49: 3605.6 | U49: 19059.8 | V49: 540.3 | W49: 2221.7 | X49: 6270.6 | Y49: 1538.7 | Z49: 10725.6 | AA49: 17681.6 | AB49: 5946.3 | AC49: 225.4 | AD49: 1182 | AE49: 2309.4 | AF49: 345.1 | AG49: 3839.8 | AH49: 1799.4 | AI49: 1987.2 | AJ49: 1484.5 | AK49: 5400.1 | AL49: 5768.8 | AM49: 5332.6 | AN49: 3270.9 | AO49: 4235.2 | AP49: 1808.7 | AQ49: 3412.4 | AR49: 1625.9 | AS49: 1578.8 | AT49: 0 | AU49: 79406.3 | AV49: 2271.2 | AW49: 33834.3 | AX49: 36737.9 | AY49: 3928.2 | AZ49: 2339.6 | BA49: 5146.4 | BB49: 105935.3 | BC49: -110695.5
A50: VALU | B50: 5480.9 | C50: 22.2 | D50: 72.9 | E50: 174.5 | F50: 83.1 | G50: 2865.9 | H50: 749.4 | I50: 442.7 | J50: 880.9 | K50: 2203 | L50: 1083.3 | M50: 1722.1 | N50: 1326 | O50: 1403.8 | P50: 1055.1 | Q50: 2124.4 | R50: 2424.1 | S50: 2617 | T50: 1687.2 | U50: 4942.2 | V50: 285.5 | W50: 1295.8 | X50: 3309.2 | Y50: 1502.8 | Z50: 6671.9 | AA50: 15031.6 | AB50: 4061.4 | AC50: 32 | AD50: 107.5 | AE50: 2621.1 | AF50: 866.8 | AG50: 2610.9 | AH50: 1726.2 | AI50: 3339.2 | AJ50: 2229.7 | AK50: 6000.2 | AL50: 11256.6 | AM50: 7347.5 | AN50: 4395.8 | AO50: 11829 | AP50: 6643.1 | AQ50: 5562.9 | AR50: 1657.2 | AS50: 2454.6 | AT50: 18.1 | AU50: 0 | AV50: 0 | AW50: 0 | AX50: 0 | AY50: 0 | AZ50: 0 | BA50: 0 | BB50: 0 | BC50: 0
A51: OUTPUT | B51: 13718.9 | C51: 60.8 | D51: 254.3 | E51: 396.2 | F51: 185.5 | G51: 14576.6 | H51: 2230.2 | I51: 1508.5 | J51: 2969.9 | K51: 9618.1 | L51: 5461.4 | M51: 3522.5 | N51: 5241.3 | O51: 4174.6 | P51: 4765.6 | Q51: 6097.2 | R51: 22717 | S51: 8214.4 | T51: 5292.8 | U51: 24001.9 | V51: 825.8 | W51: 3517.5 | X51: 9579.9 | Y51: 3041.5 | Z51: 17397.5 | AA51: 32713.2 | AB51: 10007.7 | AC51: 257.5 | AD51: 1289.4 | AE51: 4930.4 | AF51: 1211.8 | AG51: 6450.7 | AH51: 3525.6 | AI51: 5326.4 | AJ51: 3714.2 | AK51: 11400.4 | AL51: 17025.4 | AM51: 12680.1 | AN51: 7666.6 | AO51: 16064.2 | AP51: 8451.8 | AQ51: 9051 | AR51: 3308.5 | AS51: 4048.8 | AT51: 18.1 | AU51: 0 | AV51: 0 | AW51: 0 | AX51: 0 | AY51: 0 | AZ51: 0 | BA51: 0 | BB51: 0 | BC51: 0
BD53: Total Output | BE53: =SUM(BE2:BE46) -> 328510.3
B54: 3X3 MATRIX | K54: % DISTRIBUTION
B58: INDUSTRIES | C58: Primary | D58: Secondary | E58: Tertiary | F58: OUTPUT | K58: Industries | L58: HFCE | M58: NPISH | N58: GGFC | O58: GFCF | P58: INVNT | Q58: DPABR | R58: CONS_NONRES | S58: EXPO | T58: IMPO | U58: OUTPUT/GDP
B59: Primary | C59: =SUM(B2:F6) -> 3020.7 | D59: =SUM(G2:Z6) -> 8931 | E59: =SUM(AA2:AT6) -> 1370.3 | F59: =SUM(C59:E59) -> 13322 | K59: TOTAL | L59: =SUM(AU2:AU46) -> 68354.8 | M59: =SUM(AV2:AV46) -> 2250.1 | N59: =SUM(AW2:AW46) -> 33468.8 | O59: =SUM(AX2:AX46) -> 34628.1 | P59: =SUM(AY2:AY46) -> 3656.3 | Q59: =SUM(AZ2:AZ46) -> 2160.5 | R59: =SUM(BA2:BA46) -> 4726.7 | S59: =SUM(BB2:BB46) -> 102058.8 | T59: =SUM(BC2:BC46) -> -106069.4 | U59: =SUM(BE2:BE46) -> 328510.3
B60: Secondary | C60: =SUM(B7:F26) -> 3162.5 | D60: =SUM(G7:Z26) -> 68087.9 | E60: =SUM(AA7:AT26) -> 19205.5 | F60: =SUM(C60:E60) -> 90455.9 | K60: % OF OUTPUT | L60: =(L59/$U$59) -> 0.20807506 | M60: =(M59/$U$59) -> 0.0068494047 | N60: =(N59/$U$59) -> 0.10188052 | O60: =(O59/$U$59) -> 0.10540948 | P60: =(P59/$U$59) -> 0.01112994 | Q60: =(Q59/$U$59) -> 0.0065766583 | R60: =(R59/$U$59) -> 0.014388286 | S60: =(S59/$U$59) -> 0.31067154 | ... U60: =(U59/$U$59) -> 1
B61: Tertiary | C61: =SUM(B27:F46) -> 2250.5 | D61: =SUM(G27:Z46) -> 31579.7 | E61: =SUM(AA27:AT46) -> 45667.5 | F61: =SUM(C61:E61) -> 79497.7
B62: INPUT | C62: =SUM(C59:C61) -> 8433.7 | D62: =SUM(D59:D61) -> 108598.6 | E62: =SUM(E59:E61) -> 66243.3 | F62: =SUM(C62:E62) -> 183275.6
K63: CONSUMPTION | L63: =SUM(L59:N59) -> 104073.7 | M63: =L63/$L$67 -> 0.31680498
K64: INVESTMENT | L64: =SUM(O59:Q59) -> 40444.9 | M64: =L64/$L$67 -> 0.12311608
K65: EXTERNAL DEMAND ADJUSTMENT | L65: =SUM(R59:T59) -> 716.1 | M65: =L65/$L$67 -> 0.0021798403
K66: INTERMEDIATE DEMAND | L66: =SUM(B2:AT46) -> 183275.6 | M66: =L66/$L$67 -> 0.5578991
K67: OUTPUT | L67: 328510.3 | M67: =L67/$L$67 -> 1

Sheet LEONTIEF MATRIX 2008
B2: TECHNOLOGY MATRIX(A)
B5: A01_02 | C5: A03 | D5: B05_06 | E5: B07_08 | F5: B09 | G5: C10T12 | H5: C13T15 | I5: C16 | J5: C17_18 | K5: C19 | L5: C20 | M5: C21 | N5: C22 | O5: C23 | P5: C24 | Q5: C25 | R5: C26 | S5: C27 | T5: C28 | U5: C29 | V5: C30 | W5: C31T33 | X5: D | Y5: E | Z5: F | AA5: G | AB5: H49 | AC5: H50 | AD5: H51 | AE5: H52 | AF5: H53 | AG5: I | AH5: J58T60 | AI5: J61 | AJ5: J62_63 | AK5: K | AL5: L | AM5: M | AN5: N | AO5: O | AP5: P | AQ5: Q | AR5: R | AS5: S | AT5: T
A6: TTL_A01_02 | B6: =HUNGARY2008ttl!B2/HUNGARY2008ttl!$BE$2 -> 0.20534016 | C6: =HUNGARY2008ttl!C2/HUNGARY2008ttl!$BE$3 -> 0.084019769 | D6: =HUNGARY2008ttl!D2/HUNGARY2008ttl!$BE$4 -> 0.0023566379 | E6: =HUNGARY2008ttl!E2/HUNGARY2008ttl!$BE$5 -> 0.0015155342 | F6: =HUNGARY2008ttl!F2/HUNGARY2008ttl!$BE$6 -> 0.0010787487 | G6: =HUNGARY2008ttl!G2/HUNGARY2008ttl!$BE$7 -> 0.28006339 | H6: =HUNGARY2008ttl!H2/HUNGARY2008ttl!$BE$8 -> 0.0068597561 | I6: =HUNGARY2008ttl!I2/HUNGARY2008ttl!$BE$9 -> 0.068677494 | J6: =HUNGARY2008ttl!J2/HUNGARY2008ttl!$BE$10 -> 0.0036029362 | K6: =HUNGARY2008ttl!K2/HUNGARY2008ttl!$BE$11 -> 0.0018610551 | L6: =HUNGARY2008ttl!L2/HUNGARY2008ttl!$BE$12 -> 0.0034056578 | M6: =HUNGARY2008ttl!M2/HUNGARY2008ttl!$BE$13 -> 0.0055926189 | N6: =HUNGARY2008ttl!N2/HUNGARY2008ttl!$BE$14 -> 0.008890924 | O6: =HUNGARY2008ttl!O2/HUNGARY2008ttl!$BE$15 -> 0.0025394087 | P6: =HUNGARY2008ttl!P2/HUNGARY2008ttl!$BE$16 -> 0.001699681 | Q6: =HUNGARY2008ttl!Q2/HUNGARY2008ttl!$BE$17 -> 0.0016236695 | R6: =HUNGARY2008ttl!R2/HUNGARY2008ttl!$BE$18 -> 0.00083197239 | S6: =HUNGARY2008ttl!S2/HUNGARY2008ttl!$BE$19 -> 0.001740803 | T6: =HUNGARY2008ttl!T2/HUNGARY2008ttl!$BE$20 -> 0.0017192518 | U6: =HUNGARY2008ttl!U2/HUNGARY2008ttl!$BE$21 -> 0.0012707221 | V6: =HUNGARY2008ttl!V2/HUNGARY2008ttl!$BE$22 -> 0.0013320417 | W6: =HUNGARY2008ttl!W2/HUNGARY2008ttl!$BE$23 -> 0.0052876962 | X6: =HUNGARY2008ttl!X2/HUNGARY2008ttl!$BE$24 -> 0.011722705 | Y6: =HUNGARY2008ttl!Y2/HUNGARY2008ttl!$BE$25 -> 0.0029592608 | Z6: =HUNGARY2008ttl!Z2/HUNGARY2008ttl!$BE$26 -> 0.0024256916 | AA6: =HUNGARY2008ttl!AA2/HUNGARY2008ttl!$BE$27 -> 0.012628007 | AB6: =HUNGARY2008ttl!AB2/HUNGARY2008ttl!$BE$28 -> 0.0017586107 | AC6: =HUNGARY2008ttl!AC2/HUNGARY2008ttl!$BE$29 -> 0.0027184466 | AD6: =HUNGARY2008ttl!AD2/HUNGARY2008ttl!$BE$30 -> 0.0028691067 | AE6: =HUNGARY2008ttl!AE2/HUNGARY2008ttl!$BE$31 -> 0.0031843258 | AF6: =HUNGARY2008ttl!AF2/HUNGARY2008ttl!$BE$32 -> 0.00041264339 | AG6: =HUNGARY2008ttl!AG2/HUNGARY2008ttl!$BE$33 -> 0.01840196 | AH6: =HUNGARY2008ttl!AH2/HUNGARY2008ttl!$BE$34 -> 0.0024111423 | AI6: =HUNGARY2008ttl!AI2/HUNGARY2008ttl!$BE$35 -> 0.0012766597 | AJ6: =HUNGARY2008ttl!AJ2/HUNGARY2008ttl!$BE$36 -> 0.00067314683 | AK6: =HUNGARY2008ttl!AK2/HUNGARY2008ttl!$BE$37 -> 0.00053506894 | AL6: =HUNGARY2008ttl!AL2/HUNGARY2008ttl!$BE$38 -> 0.0010690036 | AM6: =HUNGARY2008ttl!AM2/HUNGARY2008ttl!$BE$39 -> 0.0022633712 | AN6: =HUNGARY2008ttl!AN2/HUNGARY2008ttl!$BE$40 -> 0.002778285 | AO6: =HUNGARY2008ttl!AO2/HUNGARY2008ttl!$BE$41 -> 0.00084659247 | AP6: =HUNGARY2008ttl!AP2/HUNGARY2008ttl!$BE$42 -> 0.00060340748 | AQ6: =HUNGARY2008ttl!AQ2/HUNGARY2008ttl!$BE$43 -> 0.0030273901 | AR6: =HUNGARY2008ttl!AR2/HUNGARY2008ttl!$BE$44 -> 0.0017229914 | AS6: =HUNGARY2008ttl!AS2/HUNGARY2008ttl!$BE$45 -> 0.0037048014 | AT6: =HUNGARY2008ttl!AT2/HUNGARY2008ttl!$BE$46 -> 0
A7: TTL_A03 | B7: =HUNGARY2008ttl!B3/HUNGARY2008ttl!$BE$2 -> 0.00013120777 | C7: =HUNGARY2008ttl!C3/HUNGARY2008ttl!$BE$3 -> 0.11861614 | D7: =HUNGARY2008ttl!D3/HUNGARY2008ttl!$BE$4 -> 0 | E7: =HUNGARY2008ttl!E3/HUNGARY2008ttl!$BE$5 -> 0 | F7: =HUNGARY2008ttl!F3/HUNGARY2008ttl!$BE$6 -> 0 | G7: =HUNGARY2008ttl!G3/HUNGARY2008ttl!$BE$7 -> 0.00018522711 | H7: =HUNGARY2008ttl!H3/HUNGARY2008ttl!$BE$8 -> 0 | I7: =HUNGARY2008ttl!I3/HUNGARY2008ttl!$BE$9 -> 0 | J7: =HUNGARY2008ttl!J3/HUNGARY2008ttl!$BE$10 -> 0 | K7: =HUNGARY2008ttl!K3/HUNGARY2008ttl!$BE$11 -> 1.0396956e-05 | L7: =HUNGARY2008ttl!L3/HUNGARY2008ttl!$BE$12 -> 0 | M7: =HUNGARY2008ttl!M3/HUNGARY2008ttl!$BE$13 -> 0 | N7: =HUNGARY2008ttl!N3/HUNGARY2008ttl!$BE$14 -> 0 | O7: =HUNGARY2008ttl!O3/HUNGARY2008ttl!$BE$15 -> 0 | P7: =HUNGARY2008ttl!P3/HUNGARY2008ttl!$BE$16 -> 0 | Q7: =HUNGARY2008ttl!Q3/HUNGARY2008ttl!$BE$17 -> 0 | R7: =HUNGARY2008ttl!R3/HUNGARY2008ttl!$BE$18 -> 4.4019703e-06 | S7: =HUNGARY2008ttl!S3/HUNGARY2008ttl!$BE$19 -> 0 | T7: =HUNGARY2008ttl!T3/HUNGARY2008ttl!$BE$20 -> 0 | U7: =HUNGARY2008ttl!U3/HUNGARY2008ttl!$BE$21 -> 8.3326042e-06 | V7: =HUNGARY2008ttl!V3/HUNGARY2008ttl!$BE$22 -> 0 | W7: =HUNGARY2008ttl!W3/HUNGARY2008ttl!$BE$23 -> 0 | X7: =HUNGARY2008ttl!X3/HUNGARY2008ttl!$BE$24 -> 1.043874e-05 | Y7: =HUNGARY2008ttl!Y3/HUNGARY2008ttl!$BE$25 -> 0 | Z7: =HUNGARY2008ttl!Z3/HUNGARY2008ttl!$BE$26 -> 1.1496169e-05 | AA7: =HUNGARY2008ttl!AA3/HUNGARY2008ttl!$BE$27 -> 1.2227555e-05 | AB7: =HUNGARY2008ttl!AB3/HUNGARY2008ttl!$BE$28 -> 0 | AC7: =HUNGARY2008ttl!AC3/HUNGARY2008ttl!$BE$29 -> 0 | AD7: =HUNGARY2008ttl!AD3/HUNGARY2008ttl!$BE$30 -> 0 | AE7: =HUNGARY2008ttl!AE3/HUNGARY2008ttl!$BE$31 -> 2.028233e-05 | AF7: =HUNGARY2008ttl!AF3/HUNGARY2008ttl!$BE$32 -> 0 | AG7: =HUNGARY2008ttl!AG3/HUNGARY2008ttl!$BE$33 -> 0.0019688701 | AH7: =HUNGARY2008ttl!AH3/HUNGARY2008ttl!$BE$34 -> 0 | AI7: =HUNGARY2008ttl!AI3/HUNGARY2008ttl!$BE$35 -> 0 | AJ7: =HUNGARY2008ttl!AJ3/HUNGARY2008ttl!$BE$36 -> 0 | AK7: =HUNGARY2008ttl!AK3/HUNGARY2008ttl!$BE$37 -> 0 | AL7: =HUNGARY2008ttl!AL3/HUNGARY2008ttl!$BE$38 -> 5.8736461e-06 | AM7: =HUNGARY2008ttl!AM3/HUNGARY2008ttl!$BE$39 -> 7.8863109e-06 | AN7: =HUNGARY2008ttl!AN3/HUNGARY2008ttl!$BE$40 -> 1.3043592e-05 | AO7: =HUNGARY2008ttl!AO3/HUNGARY2008ttl!$BE$41 -> 0 | AP7: =HUNGARY2008ttl!AP3/HUNGARY2008ttl!$BE$42 -> 0 | AQ7: =HUNGARY2008ttl!AQ3/HUNGARY2008ttl!$BE$43 -> 1.1048869e-05 | AR7: =HUNGARY2008ttl!AR3/HUNGARY2008ttl!$BE$44 -> 0.00012091167 | AS7: =HUNGARY2008ttl!AS3/HUNGARY2008ttl!$BE$45 -> 2.4698676e-05 | AT7: =HUNGARY2008ttl!AT3/HUNGARY2008ttl!$BE$46 -> 0
A8: TTL_B05_06 | B8: =HUNGARY2008ttl!B4/HUNGARY2008ttl!$BE$2 -> 0.0028501243 | C8: =HUNGARY2008ttl!C4/HUNGARY2008ttl!$BE$3 -> 0.0016474465 | D8: =HUNGARY2008ttl!D4/HUNGARY2008ttl!$BE$4 -> 0.060094266 | E8: =HUNGARY2008ttl!E4/HUNGARY2008ttl!$BE$5 -> 0.029300328 | F8: =HUNGARY2008ttl!F4/HUNGARY2008ttl!$BE$6 -> 0.003236246 | G8: =HUNGARY2008ttl!G4/HUNGARY2008ttl!$BE$7 -> 0.0035330356 | H8: =HUNGARY2008ttl!H4/HUNGARY2008ttl!$BE$8 -> 0.00098637016 | I8: =HUNGARY2008ttl!I4/HUNGARY2008ttl!$BE$9 -> 0.0013921114 | J8: =HUNGARY2008ttl!J4/HUNGARY2008ttl!$BE$10 -> 0.0031651963 | K8: =HUNGARY2008ttl!K4/HUNGARY2008ttl!$BE$11 -> 0.23049011 | L8: =HUNGARY2008ttl!L4/HUNGARY2008ttl!$BE$12 -> 0.024242424 | M8: =HUNGARY2008ttl!M4/HUNGARY2008ttl!$BE$13 -> 0.0030943932 | N8: =HUNGARY2008ttl!N4/HUNGARY2008ttl!$BE$14 -> 0.00053421861 | O8: =HUNGARY2008ttl!O4/HUNGARY2008ttl!$BE$15 -> 0.014469839 | P8: =HUNGARY2008ttl!P4/HUNGARY2008ttl!$BE$16 -> 0.035441497 | Q8: =HUNGARY2008ttl!Q4/HUNGARY2008ttl!$BE$17 -> 0.00078723369 | R8: =HUNGARY2008ttl!R4/HUNGARY2008ttl!$BE$18 -> 0.00022890246 | S8: =HUNGARY2008ttl!S4/HUNGARY2008ttl!$BE$19 -> 0.00042607065 | T8: =HUNGARY2008ttl!T4/HUNGARY2008ttl!$BE$20 -> 0.00068014359 | U8: =HUNGARY2008ttl!U4/HUNGARY2008ttl!$BE$21 -> 0.00053745297 | V8: =HUNGARY2008ttl!V4/HUNGARY2008ttl!$BE$22 -> 0.0032695568 | W8: =HUNGARY2008ttl!W4/HUNGARY2008ttl!$BE$23 -> 0.00039799864 | X8: =HUNGARY2008ttl!X4/HUNGARY2008ttl!$BE$24 -> 0.10877167 | Y8: =HUNGARY2008ttl!Y4/HUNGARY2008ttl!$BE$25 -> 0.0037483971 | Z8: =HUNGARY2008ttl!Z4/HUNGARY2008ttl!$BE$26 -> 0.0025464014 | AA8: =HUNGARY2008ttl!AA4/HUNGARY2008ttl!$BE$27 -> 0.0022009599 | AB8: =HUNGARY2008ttl!AB4/HUNGARY2008ttl!$BE$28 -> 0.0051958952 | AC8: =HUNGARY2008ttl!AC4/HUNGARY2008ttl!$BE$29 -> 0.0015533981 | AD8: =HUNGARY2008ttl!AD4/HUNGARY2008ttl!$BE$30 -> 0.0013957816 | AE8: =HUNGARY2008ttl!AE4/HUNGARY2008ttl!$BE$31 -> 0.0089039429 | AF8: =HUNGARY2008ttl!AF4/HUNGARY2008ttl!$BE$32 -> 0.0019806883 | AG8: =HUNGARY2008ttl!AG4/HUNGARY2008ttl!$BE$33 -> 0.0051779735 | AH8: =HUNGARY2008ttl!AH4/HUNGARY2008ttl!$BE$34 -> 0.0007091595 | AI8: =HUNGARY2008ttl!AI4/HUNGARY2008ttl!$BE$35 -> 0.00091994593 | AJ8: =HUNGARY2008ttl!AJ4/HUNGARY2008ttl!$BE$36 -> 0.0004038881 | AK8: =HUNGARY2008ttl!AK4/HUNGARY2008ttl!$BE$37 -> 0.00057892706 | AL8: =HUNGARY2008ttl!AL4/HUNGARY2008ttl!$BE$38 -> 0.0014096751 | AM8: =HUNGARY2008ttl!AM4/HUNGARY2008ttl!$BE$39 -> 0.0029100487 | AN8: =HUNGARY2008ttl!AN4/HUNGARY2008ttl!$BE$40 -> 0.0019956695 | AO8: =HUNGARY2008ttl!AO4/HUNGARY2008ttl!$BE$41 -> 0.0031622719 | AP8: =HUNGARY2008ttl!AP4/HUNGARY2008ttl!$BE$42 -> 0.0059985802 | AQ8: =HUNGARY2008ttl!AQ4/HUNGARY2008ttl!$BE$43 -> 0.0069607876 | AR8: =HUNGARY2008ttl!AR4/HUNGARY2008ttl!$BE$44 -> 0.0088567801 | AS8: =HUNGARY2008ttl!AS4/HUNGARY2008ttl!$BE$45 -> 0.0022475795 | AT8: =HUNGARY2008ttl!AT4/HUNGARY2008ttl!$BE$46 -> 0
A9: TTL_B07_08 | B9: =HUNGARY2008ttl!B5/HUNGARY2008ttl!$BE$2 -> 0.0015307573 | C9: =HUNGARY2008ttl!C5/HUNGARY2008ttl!$BE$3 -> 0 | D9: =HUNGARY2008ttl!D5/HUNGARY2008ttl!$BE$4 -> 0.10644148 | E9: =HUNGARY2008ttl!E5/HUNGARY2008ttl!$BE$5 -> 0.043697904 | F9: =HUNGARY2008ttl!F5/HUNGARY2008ttl!$BE$6 -> 0.042610572 | G9: =HUNGARY2008ttl!G5/HUNGARY2008ttl!$BE$7 -> 0.0035193151 | H9: =HUNGARY2008ttl!H5/HUNGARY2008ttl!$BE$8 -> 0.00053802009 | I9: =HUNGARY2008ttl!I5/HUNGARY2008ttl!$BE$9 -> 0.0010606563 | J9: =HUNGARY2008ttl!J5/HUNGARY2008ttl!$BE$10 -> 0.0016836151 | K9: =HUNGARY2008ttl!K5/HUNGARY2008ttl!$BE$11 -> 0.00010396956 | L9: =HUNGARY2008ttl!L5/HUNGARY2008ttl!$BE$12 -> 0.0026366383 | M9: =HUNGARY2008ttl!M5/HUNGARY2008ttl!$BE$13 -> 0.00048261178 | N9: =HUNGARY2008ttl!N5/HUNGARY2008ttl!$BE$14 -> 0.0016026558 | O9: =HUNGARY2008ttl!O5/HUNGARY2008ttl!$BE$15 -> 0.03274879 | P9: =HUNGARY2008ttl!P5/HUNGARY2008ttl!$BE$16 -> 0.0065469196 | Q9: =HUNGARY2008ttl!Q5/HUNGARY2008ttl!$BE$17 -> 0.003411346 | R9: =HUNGARY2008ttl!R5/HUNGARY2008ttl!$BE$18 -> 0.00027292216 | S9: =HUNGARY2008ttl!S5/HUNGARY2008ttl!$BE$19 -> 0.0012660385 | T9: =HUNGARY2008ttl!T5/HUNGARY2008ttl!$BE$20 -> 0.0014925373 | U9: =HUNGARY2008ttl!U5/HUNGARY2008ttl!$BE$21 -> 0.00068743985 | V9: =HUNGARY2008ttl!V5/HUNGARY2008ttl!$BE$22 -> 0.00060547348 | W9: =HUNGARY2008ttl!W5/HUNGARY2008ttl!$BE$23 -> 0.0010234251 | X9: =HUNGARY2008ttl!X5/HUNGARY2008ttl!$BE$24 -> 0.00021921355 | Y9: =HUNGARY2008ttl!Y5/HUNGARY2008ttl!$BE$25 -> 0.0018413179 | Z9: =HUNGARY2008ttl!Z5/HUNGARY2008ttl!$BE$26 -> 0.0081622799 | AA9: =HUNGARY2008ttl!AA5/HUNGARY2008ttl!$BE$27 -> 0.0010271146 | AB9: =HUNGARY2008ttl!AB5/HUNGARY2008ttl!$BE$28 -> 0.00012989738 | AC9: =HUNGARY2008ttl!AC5/HUNGARY2008ttl!$BE$29 -> 0.00077669903 | AD9: =HUNGARY2008ttl!AD5/HUNGARY2008ttl!$BE$30 -> 0 | AE9: =HUNGARY2008ttl!AE5/HUNGARY2008ttl!$BE$31 -> 0.00038536427 | AF9: =HUNGARY2008ttl!AF5/HUNGARY2008ttl!$BE$32 -> 0 | AG9: =HUNGARY2008ttl!AG5/HUNGARY2008ttl!$BE$33 -> 6.2011658e-05 | AH9: =HUNGARY2008ttl!AH5/HUNGARY2008ttl!$BE$34 -> 0.00011346552 | AI9: =HUNGARY2008ttl!AI5/HUNGARY2008ttl!$BE$35 -> 3.7548813e-05 | AJ9: =HUNGARY2008ttl!AJ5/HUNGARY2008ttl!$BE$36 -> 0.00035003635 | AK9: =HUNGARY2008ttl!AK5/HUNGARY2008ttl!$BE$37 -> 1.7543244e-05 | AL9: =HUNGARY2008ttl!AL5/HUNGARY2008ttl!$BE$38 -> 0.0030484223 | AM9: =HUNGARY2008ttl!AM5/HUNGARY2008ttl!$BE$39 -> 0.00074919954 | AN9: =HUNGARY2008ttl!AN5/HUNGARY2008ttl!$BE$40 -> 0.00033913338 | AO9: =HUNGARY2008ttl!AO5/HUNGARY2008ttl!$BE$41 -> 0.00012449889 | AP9: =HUNGARY2008ttl!AP5/HUNGARY2008ttl!$BE$42 -> 0.00023663038 | AQ9: =HUNGARY2008ttl!AQ5/HUNGARY2008ttl!$BE$43 -> 0.0005745412 | AR9: =HUNGARY2008ttl!AR5/HUNGARY2008ttl!$BE$44 -> 0.00063478629 | AS9: =HUNGARY2008ttl!AS5/HUNGARY2008ttl!$BE$45 -> 0.0014078245 | AT9: =HUNGARY2008ttl!AT5/HUNGARY2008ttl!$BE$46 -> 0
A10: TTL_B09 | B10: =HUNGARY2008ttl!B6/HUNGARY2008ttl!$BE$2 -> 2.9157282e-05 | C10: =HUNGARY2008ttl!C6/HUNGARY2008ttl!$BE$3 -> 0 | D10: =HUNGARY2008ttl!D6/HUNGARY2008ttl!$BE$4 -> 0.14925373 | E10: =HUNGARY2008ttl!E6/HUNGARY2008ttl!$BE$5 -> 0.0015155342 | F10: =HUNGARY2008ttl!F6/HUNGARY2008ttl!$BE$6 -> 0.049622438 | G10: =HUNGARY2008ttl!G6/HUNGARY2008ttl!$BE$7 -> 3.4301316e-05 | H10: =HUNGARY2008ttl!H6/HUNGARY2008ttl!$BE$8 -> 0 | I10: =HUNGARY2008ttl!I6/HUNGARY2008ttl!$BE$9 -> 0.00013258204 | J10: =HUNGARY2008ttl!J6/HUNGARY2008ttl!$BE$10 -> 3.3672301e-05 | K10: =HUNGARY2008ttl!K6/HUNGARY2008ttl!$BE$11 -> 0.0048761723 | L10: =HUNGARY2008ttl!L6/HUNGARY2008ttl!$BE$12 -> 0.00018309988 | M10: =HUNGARY2008ttl!M6/HUNGARY2008ttl!$BE$13 -> 2.8388928e-05 | N10: =HUNGARY2008ttl!N6/HUNGARY2008ttl!$BE$14 -> 0.00013355465 | O10: =HUNGARY2008ttl!O6/HUNGARY2008ttl!$BE$15 -> 0.00011978343 | P10: =HUNGARY2008ttl!P6/HUNGARY2008ttl!$BE$16 -> 0.00060852778 | Q10: =HUNGARY2008ttl!Q6/HUNGARY2008ttl!$BE$17 -> 1.6400702e-05 | R10: =HUNGARY2008ttl!R6/HUNGARY2008ttl!$BE$18 -> 2.2009852e-05 | S10: =HUNGARY2008ttl!S6/HUNGARY2008ttl!$BE$19 -> 2.4346895e-05 | T10: =HUNGARY2008ttl!T6/HUNGARY2008ttl!$BE$20 -> 7.557151e-05 | U10: =HUNGARY2008ttl!U6/HUNGARY2008ttl!$BE$21 -> 7.4993438e-05 | V10: =HUNGARY2008ttl!V6/HUNGARY2008ttl!$BE$22 -> 0.0001210947 | W10: =HUNGARY2008ttl!W6/HUNGARY2008ttl!$BE$23 -> 0.00014214237 | X10: =HUNGARY2008ttl!X6/HUNGARY2008ttl!$BE$24 -> 0.00083509922 | Y10: =HUNGARY2008ttl!Y6/HUNGARY2008ttl!$BE$25 -> 6.5761352e-05 | Z10: =HUNGARY2008ttl!Z6/HUNGARY2008ttl!$BE$26 -> 0.00035063315 | AA10: =HUNGARY2008ttl!AA6/HUNGARY2008ttl!$BE$27 -> 3.6682664e-05 | AB10: =HUNGARY2008ttl!AB6/HUNGARY2008ttl!$BE$28 -> 4.9960531e-05 | AC10: =HUNGARY2008ttl!AC6/HUNGARY2008ttl!$BE$29 -> 0 | AD10: =HUNGARY2008ttl!AD6/HUNGARY2008ttl!$BE$30 -> 0 | AE10: =HUNGARY2008ttl!AE6/HUNGARY2008ttl!$BE$31 -> 8.112932e-05 | AF10: =HUNGARY2008ttl!AF6/HUNGARY2008ttl!$BE$32 -> 0 | AG10: =HUNGARY2008ttl!AG6/HUNGARY2008ttl!$BE$33 -> 4.6508744e-05 | AH10: =HUNGARY2008ttl!AH6/HUNGARY2008ttl!$BE$34 -> 2.836638e-05 | AI10: =HUNGARY2008ttl!AI6/HUNGARY2008ttl!$BE$35 -> 1.8774407e-05 | AJ10: =HUNGARY2008ttl!AJ6/HUNGARY2008ttl!$BE$36 -> 2.6925873e-05 | AK10: =HUNGARY2008ttl!AK6/HUNGARY2008ttl!$BE$37 -> 1.7543244e-05 | AL10: =HUNGARY2008ttl!AL6/HUNGARY2008ttl!$BE$38 -> 2.9368231e-05 | AM10: =HUNGARY2008ttl!AM6/HUNGARY2008ttl!$BE$39 -> 6.3090488e-05 | AN10: =HUNGARY2008ttl!AN6/HUNGARY2008ttl!$BE$40 -> 3.9130775e-05 | AO10: =HUNGARY2008ttl!AO6/HUNGARY2008ttl!$BE$41 -> 2.4899778e-05 | AP10: =HUNGARY2008ttl!AP6/HUNGARY2008ttl!$BE$42 -> 3.5494558e-05 | AQ10: =HUNGARY2008ttl!AQ6/HUNGARY2008ttl!$BE$43 -> 7.7342084e-05 | AR10: =HUNGARY2008ttl!AR6/HUNGARY2008ttl!$BE$44 -> 9.0683756e-05 | AS10: =HUNGARY2008ttl!AS6/HUNGARY2008ttl!$BE$45 -> 2.4698676e-05 | AT10: =HUNGARY2008ttl!AT6/HUNGARY2008ttl!$BE$46 -> 0
A11: TTL_C10T12 | B11: =HUNGARY2008ttl!B7/HUNGARY2008ttl!$BE$2 -> 0.069583853 | C11: =HUNGARY2008ttl!C7/HUNGARY2008ttl!$BE$3 -> 0.047775947 | D11: =HUNGARY2008ttl!D7/HUNGARY2008ttl!$BE$4 -> 0.0039277298 | E11: =HUNGARY2008ttl!E7/HUNGARY2008ttl!$BE$5 -> 0.00075776711 | F11: =HUNGARY2008ttl!F7/HUNGARY2008ttl!$BE$6 -> 0.00053937433 | G11: =HUNGARY2008ttl!G7/HUNGARY2008ttl!$BE$7 -> 0.094239437 | H11: =HUNGARY2008ttl!H7/HUNGARY2008ttl!$BE$8 -> 0.0022417504 | I11: =HUNGARY2008ttl!I7/HUNGARY2008ttl!$BE$9 -> 0.0014584024 | J11: =HUNGARY2008ttl!J7/HUNGARY2008ttl!$BE$10 -> 0.0058253081 | K11: =HUNGARY2008ttl!K7/HUNGARY2008ttl!$BE$11 -> 0.0045122788 | L11: =HUNGARY2008ttl!L7/HUNGARY2008ttl!$BE$12 -> 0.0047972169 | M11: =HUNGARY2008ttl!M7/HUNGARY2008ttl!$BE$13 -> 0.0049112846 | N11: =HUNGARY2008ttl!N7/HUNGARY2008ttl!$BE$14 -> 0.0029572816 | O11: =HUNGARY2008ttl!O7/HUNGARY2008ttl!$BE$15 -> 0.0013655311 | P11: =HUNGARY2008ttl!P7/HUNGARY2008ttl!$BE$16 -> 0.00098623468 | Q11: =HUNGARY2008ttl!Q7/HUNGARY2008ttl!$BE$17 -> 0.0010332442 | R11: =HUNGARY2008ttl!R7/HUNGARY2008ttl!$BE$18 -> 0.00077034481 | S11: =HUNGARY2008ttl!S7/HUNGARY2008ttl!$BE$19 -> 0.0012416916 | T11: =HUNGARY2008ttl!T7/HUNGARY2008ttl!$BE$20 -> 0.00090685811 | U11: =HUNGARY2008ttl!U7/HUNGARY2008ttl!$BE$21 -> 0.00075826698 | V11: =HUNGARY2008ttl!V7/HUNGARY2008ttl!$BE$22 -> 0.00084766287 | W11: =HUNGARY2008ttl!W7/HUNGARY2008ttl!$BE$23 -> 0.0015635661 | X11: =HUNGARY2008ttl!X7/HUNGARY2008ttl!$BE$24 -> 0.0027453887 | Y11: =HUNGARY2008ttl!Y7/HUNGARY2008ttl!$BE$25 -> 0.001019301 | Z11: =HUNGARY2008ttl!Z7/HUNGARY2008ttl!$BE$26 -> 0.00093118968 | AA11: =HUNGARY2008ttl!AA7/HUNGARY2008ttl!$BE$27 -> 0.0069085685 | AB11: =HUNGARY2008ttl!AB7/HUNGARY2008ttl!$BE$28 -> 0.00066947112 | AC11: =HUNGARY2008ttl!AC7/HUNGARY2008ttl!$BE$29 -> 0.0089320388 | AD11: =HUNGARY2008ttl!AD7/HUNGARY2008ttl!$BE$30 -> 0.0037996278 | AE11: =HUNGARY2008ttl!AE7/HUNGARY2008ttl!$BE$31 -> 0.0004056466 | AF11: =HUNGARY2008ttl!AF7/HUNGARY2008ttl!$BE$32 -> 0.00049517207 | AG11: =HUNGARY2008ttl!AG7/HUNGARY2008ttl!$BE$33 -> 0.2015999 | AH11: =HUNGARY2008ttl!AH7/HUNGARY2008ttl!$BE$34 -> 0.00062406036 | AI11: =HUNGARY2008ttl!AI7/HUNGARY2008ttl!$BE$35 -> 0.00033793932 | AJ11: =HUNGARY2008ttl!AJ7/HUNGARY2008ttl!$BE$36 -> 0.00045773984 | AK11: =HUNGARY2008ttl!AK7/HUNGARY2008ttl!$BE$37 -> 0.00042980948 | AL11: =HUNGARY2008ttl!AL7/HUNGARY2008ttl!$BE$38 -> 0.0010572563 | AM11: =HUNGARY2008ttl!AM7/HUNGARY2008ttl!$BE$39 -> 0.0020662135 | AN11: =HUNGARY2008ttl!AN7/HUNGARY2008ttl!$BE$40 -> 0.0064304907 | AO11: =HUNGARY2008ttl!AO7/HUNGARY2008ttl!$BE$41 -> 0.0018986081 | AP11: =HUNGARY2008ttl!AP7/HUNGARY2008ttl!$BE$42 -> 0.00067439659 | AQ11: =HUNGARY2008ttl!AQ7/HUNGARY2008ttl!$BE$43 -> 0.014573458 | AR11: =HUNGARY2008ttl!AR7/HUNGARY2008ttl!$BE$44 -> 0.0035064385 | AS11: =HUNGARY2008ttl!AS7/HUNGARY2008ttl!$BE$45 -> 0.0034825133 | AT11: =HUNGARY2008ttl!AT7/HUNGARY2008ttl!$BE$46 -> 0
A12: TTL_C13T15 | B12: =HUNGARY2008ttl!B8/HUNGARY2008ttl!$BE$2 -> 0.00046651651 | C12: =HUNGARY2008ttl!C8/HUNGARY2008ttl!$BE$3 -> 0.0016474465 | D12: =HUNGARY2008ttl!D8/HUNGARY2008ttl!$BE$4 -> 0.00078554595 | E12: =HUNGARY2008ttl!E8/HUNGARY2008ttl!$BE$5 -> 0.00075776711 | F12: =HUNGARY2008ttl!F8/HUNGARY2008ttl!$BE$6 -> 0.00053937433 | G12: =HUNGARY2008ttl!G8/HUNGARY2008ttl!$BE$7 -> 0.00085753291 | H12: =HUNGARY2008ttl!H8/HUNGARY2008ttl!$BE$8 -> 0.21014168 | I12: =HUNGARY2008ttl!I8/HUNGARY2008ttl!$BE$9 -> 0.0011269473 | J12: =HUNGARY2008ttl!J8/HUNGARY2008ttl!$BE$10 -> 0.0028958179 | K12: =HUNGARY2008ttl!K8/HUNGARY2008ttl!$BE$11 -> 0.00022873303 | L12: =HUNGARY2008ttl!L8/HUNGARY2008ttl!$BE$12 -> 0.00084225945 | M12: =HUNGARY2008ttl!M8/HUNGARY2008ttl!$BE$13 -> 0.00099361249 | N12: =HUNGARY2008ttl!N8/HUNGARY2008ttl!$BE$14 -> 0.0095586973 | O12: =HUNGARY2008ttl!O8/HUNGARY2008ttl!$BE$15 -> 0.0014134445 | P12: =HUNGARY2008ttl!P8/HUNGARY2008ttl!$BE$16 -> 0.00071344637 | Q12: =HUNGARY2008ttl!Q8/HUNGARY2008ttl!$BE$17 -> 0.00072163089 | R12: =HUNGARY2008ttl!R8/HUNGARY2008ttl!$BE$18 -> 0.00091560983 | S12: =HUNGARY2008ttl!S8/HUNGARY2008ttl!$BE$19 -> 0.0016190685 | T12: =HUNGARY2008ttl!T8/HUNGARY2008ttl!$BE$20 -> 0.0021160023 | U12: =HUNGARY2008ttl!U8/HUNGARY2008ttl!$BE$21 -> 0.0048870724 | V12: =HUNGARY2008ttl!V8/HUNGARY2008ttl!$BE$22 -> 0.00096875757 | W12: =HUNGARY2008ttl!W8/HUNGARY2008ttl!$BE$23 -> 0.020553787 | X12: =HUNGARY2008ttl!X8/HUNGARY2008ttl!$BE$24 -> 0.00038623339 | Y12: =HUNGARY2008ttl!Y8/HUNGARY2008ttl!$BE$25 -> 0.001315227 | Z12: =HUNGARY2008ttl!Z8/HUNGARY2008ttl!$BE$26 -> 0.0010404033 | AA12: =HUNGARY2008ttl!AA8/HUNGARY2008ttl!$BE$27 -> 0.0012380399 | AB12: =HUNGARY2008ttl!AB8/HUNGARY2008ttl!$BE$28 -> 0.00043965267 | AC12: =HUNGARY2008ttl!AC8/HUNGARY2008ttl!$BE$29 -> 0.00077669903 | AD12: =HUNGARY2008ttl!AD8/HUNGARY2008ttl!$BE$30 -> 0.00046526055 | AE12: =HUNGARY2008ttl!AE8/HUNGARY2008ttl!$BE$31 -> 0.00048677592 | AF12: =HUNGARY2008ttl!AF8/HUNGARY2008ttl!$BE$32 -> 0.0010728728 | AG12: =HUNGARY2008ttl!AG8/HUNGARY2008ttl!$BE$33 -> 0.0012247302 | AH12: =HUNGARY2008ttl!AH8/HUNGARY2008ttl!$BE$34 -> 0.00034039656 | AI12: =HUNGARY2008ttl!AI8/HUNGARY2008ttl!$BE$35 -> 0.00035671373 | AJ12: =HUNGARY2008ttl!AJ8/HUNGARY2008ttl!$BE$36 -> 0.00037696222 | AK12: =HUNGARY2008ttl!AK8/HUNGARY2008ttl!$BE$37 -> 0.00021051893 | AL12: =HUNGARY2008ttl!AL8/HUNGARY2008ttl!$BE$38 -> 0.00031717689 | AM12: =HUNGARY2008ttl!AM8/HUNGARY2008ttl!$BE$39 -> 0.00045740603 | AN12: =HUNGARY2008ttl!AN8/HUNGARY2008ttl!$BE$40 -> 0.0012652284 | AO12: =HUNGARY2008ttl!AO8/HUNGARY2008ttl!$BE$41 -> 0.00061626952 | AP12: =HUNGARY2008ttl!AP8/HUNGARY2008ttl!$BE$42 -> 0.00027212494 | AQ12: =HUNGARY2008ttl!AQ8/HUNGARY2008ttl!$BE$43 -> 0.0020882363 | AR12: =HUNGARY2008ttl!AR8/HUNGARY2008ttl!$BE$44 -> 0.0019950426 | AS12: =HUNGARY2008ttl!AS8/HUNGARY2008ttl!$BE$45 -> 0.0056065995 | AT12: =HUNGARY2008ttl!AT8/HUNGARY2008ttl!$BE$46 -> 0
A13: TTL_C16 | B13: =HUNGARY2008ttl!B9/HUNGARY2008ttl!$BE$2 -> 0.0021503495 | C13: =HUNGARY2008ttl!C9/HUNGARY2008ttl!$BE$3 -> 0.0016474465 | D13: =HUNGARY2008ttl!D9/HUNGARY2008ttl!$BE$4 -> 0.00039277298 | E13: =HUNGARY2008ttl!E9/HUNGARY2008ttl!$BE$5 -> 0.00050517808 | F13: =HUNGARY2008ttl!F9/HUNGARY2008ttl!$BE$6 -> 0 | G13: =HUNGARY2008ttl!G9/HUNGARY2008ttl!$BE$7 -> 0.0018728519 | H13: =HUNGARY2008ttl!H9/HUNGARY2008ttl!$BE$8 -> 0.0025555954 | I13: =HUNGARY2008ttl!I9/HUNGARY2008ttl!$BE$9 -> 0.20715943 | J13: =HUNGARY2008ttl!J9/HUNGARY2008ttl!$BE$10 -> 0.0023570611 | K13: =HUNGARY2008ttl!K9/HUNGARY2008ttl!$BE$11 -> 0.00022873303 | L13: =HUNGARY2008ttl!L9/HUNGARY2008ttl!$BE$12 -> 0.0029295981 | M13: =HUNGARY2008ttl!M9/HUNGARY2008ttl!$BE$13 -> 0.00045422285 | N13: =HUNGARY2008ttl!N9/HUNGARY2008ttl!$BE$14 -> 0.003472421 | O13: =HUNGARY2008ttl!O9/HUNGARY2008ttl!$BE$15 -> 0.0080015332 | P13: =HUNGARY2008ttl!P9/HUNGARY2008ttl!$BE$16 -> 0.0021193554 | Q13: =HUNGARY2008ttl!Q9/HUNGARY2008ttl!$BE$17 -> 0.0049202106 | R13: =HUNGARY2008ttl!R9/HUNGARY2008ttl!$BE$18 -> 0.0010168551 | S13: =HUNGARY2008ttl!S9/HUNGARY2008ttl!$BE$19 -> 0.0028485867 | T13: =HUNGARY2008ttl!T9/HUNGARY2008ttl!$BE$20 -> 0.0029850746 | U13: =HUNGARY2008ttl!U9/HUNGARY2008ttl!$BE$21 -> 0.0019206653 | V13: =HUNGARY2008ttl!V9/HUNGARY2008ttl!$BE$22 -> 0.0032695568 | W13: =HUNGARY2008ttl!W9/HUNGARY2008ttl!$BE$23 -> 0.050432113 | X13: =HUNGARY2008ttl!X9/HUNGARY2008ttl!$BE$24 -> 0.0023069616 | Y13: =HUNGARY2008ttl!Y9/HUNGARY2008ttl!$BE$25 -> 0.00092065893 | Z13: =HUNGARY2008ttl!Z9/HUNGARY2008ttl!$BE$26 -> 0.021083974 | AA13: =HUNGARY2008ttl!AA9/HUNGARY2008ttl!$BE$27 -> 0.0025708434 | AB13: =HUNGARY2008ttl!AB9/HUNGARY2008ttl!$BE$28 -> 0.0011391001 | AC13: =HUNGARY2008ttl!AC9/HUNGARY2008ttl!$BE$29 -> 0.0019417476 | AD13: =HUNGARY2008ttl!AD9/HUNGARY2008ttl!$BE$30 -> 0.00046526055 | AE13: =HUNGARY2008ttl!AE9/HUNGARY2008ttl!$BE$31 -> 0.00044621126 | AF13: =HUNGARY2008ttl!AF9/HUNGARY2008ttl!$BE$32 -> 0.00024758604 | AG13: =HUNGARY2008ttl!AG9/HUNGARY2008ttl!$BE$33 -> 0.00093017487 | AH13: =HUNGARY2008ttl!AH9/HUNGARY2008ttl!$BE$34 -> 0.00022693104 | AI13: =HUNGARY2008ttl!AI9/HUNGARY2008ttl!$BE$35 -> 0.00052568339 | AJ13: =HUNGARY2008ttl!AJ9/HUNGARY2008ttl!$BE$36 -> 0.00010770349 | AK13: =HUNGARY2008ttl!AK9/HUNGARY2008ttl!$BE$37 -> 0.00010525946 | AL13: =HUNGARY2008ttl!AL9/HUNGARY2008ttl!$BE$38 -> 0.0042525198 | AM13: =HUNGARY2008ttl!AM9/HUNGARY2008ttl!$BE$39 -> 0.001648239 | AN13: =HUNGARY2008ttl!AN9/HUNGARY2008ttl!$BE$40 -> 0.0013434899 | AO13: =HUNGARY2008ttl!AO9/HUNGARY2008ttl!$BE$41 -> 0.00020542317 | AP13: =HUNGARY2008ttl!AP9/HUNGARY2008ttl!$BE$42 -> 8.2820634e-05 | AQ13: =HUNGARY2008ttl!AQ9/HUNGARY2008ttl!$BE$43 -> 0.00037566155 | AR13: =HUNGARY2008ttl!AR9/HUNGARY2008ttl!$BE$44 -> 0.0004836467 | AS13: =HUNGARY2008ttl!AS9/HUNGARY2008ttl!$BE$45 -> 0.0014819206 | AT13: =HUNGARY2008ttl!AT9/HUNGARY2008ttl!$BE$46 -> 0
A14: TTL_C17_18 | B14: =HUNGARY2008ttl!B10/HUNGARY2008ttl!$BE$2 -> 0.0021722175 | C14: =HUNGARY2008ttl!C10/HUNGARY2008ttl!$BE$3 -> 0.0016474465 | D14: =HUNGARY2008ttl!D10/HUNGARY2008ttl!$BE$4 -> 0.00039277298 | E14: =HUNGARY2008ttl!E10/HUNGARY2008ttl!$BE$5 -> 0.0012629452 | F14: =HUNGARY2008ttl!F10/HUNGARY2008ttl!$BE$6 -> 0 | G14: =HUNGARY2008ttl!G10/HUNGARY2008ttl!$BE$7 -> 0.02136972 | H14: =HUNGARY2008ttl!H10/HUNGARY2008ttl!$BE$8 -> 0.006052726 | I14: =HUNGARY2008ttl!I10/HUNGARY2008ttl!$BE$9 -> 0.019887305 | J14: =HUNGARY2008ttl!J10/HUNGARY2008ttl!$BE$10 -> 0.31665432 | K14: =HUNGARY2008ttl!K10/HUNGARY2008ttl!$BE$11 -> 0.00038468736 | L14: =HUNGARY2008ttl!L10/HUNGARY2008ttl!$BE$12 -> 0.0089352742 | M14: =HUNGARY2008ttl!M10/HUNGARY2008ttl!$BE$13 -> 0.0072959546 | N14: =HUNGARY2008ttl!N10/HUNGARY2008ttl!$BE$14 -> 0.011848206 | O14: =HUNGARY2008ttl!O10/HUNGARY2008ttl!$BE$15 -> 0.0062047818 | P14: =HUNGARY2008ttl!P10/HUNGARY2008ttl!$BE$16 -> 0.0013219741 | Q14: =HUNGARY2008ttl!Q10/HUNGARY2008ttl!$BE$17 -> 0.0025913109 | R14: =HUNGARY2008ttl!R10/HUNGARY2008ttl!$BE$18 -> 0.0034379388 | S14: =HUNGARY2008ttl!S10/HUNGARY2008ttl!$BE$19 -> 0.0099944002 | T14: =HUNGARY2008ttl!T10/HUNGARY2008ttl!$BE$20 -> 0.0027583601 | U14: =HUNGARY2008ttl!U10/HUNGARY2008ttl!$BE$21 -> 0.0015873611 | V14: =HUNGARY2008ttl!V10/HUNGARY2008ttl!$BE$22 -> 0.0018164204 | W14: =HUNGARY2008ttl!W10/HUNGARY2008ttl!$BE$23 -> 0.0090686832 | X14: =HUNGARY2008ttl!X10/HUNGARY2008ttl!$BE$24 -> 0.0017954633 | Y14: =HUNGARY2008ttl!Y10/HUNGARY2008ttl!$BE$25 -> 0.001315227 | Z14: =HUNGARY2008ttl!Z10/HUNGARY2008ttl!$BE$26 -> 0.00098292244 | AA14: =HUNGARY2008ttl!AA10/HUNGARY2008ttl!$BE$27 -> 0.013233271 | AB14: =HUNGARY2008ttl!AB10/HUNGARY2008ttl!$BE$28 -> 0.001408887 | AC14: =HUNGARY2008ttl!AC10/HUNGARY2008ttl!$BE$29 -> 0.00077669903 | AD14: =HUNGARY2008ttl!AD10/HUNGARY2008ttl!$BE$30 -> 0.00085297767 | AE14: =HUNGARY2008ttl!AE10/HUNGARY2008ttl!$BE$31 -> 0.0027178322 | AF14: =HUNGARY2008ttl!AF10/HUNGARY2008ttl!$BE$32 -> 0.0063547083 | AG14: =HUNGARY2008ttl!AG10/HUNGARY2008ttl!$BE$33 -> 0.0023254372 | AH14: =HUNGARY2008ttl!AH10/HUNGARY2008ttl!$BE$34 -> 0.098885201 | AI14: =HUNGARY2008ttl!AI10/HUNGARY2008ttl!$BE$35 -> 0.0014080805 | AJ14: =HUNGARY2008ttl!AJ10/HUNGARY2008ttl!$BE$36 -> 0.003608067 | AK14: =HUNGARY2008ttl!AK10/HUNGARY2008ttl!$BE$37 -> 0.0095873829 | AL14: =HUNGARY2008ttl!AL10/HUNGARY2008ttl!$BE$38 -> 0.0040763104 | AM14: =HUNGARY2008ttl!AM10/HUNGARY2008ttl!$BE$39 -> 0.0055677355 | AN14: =HUNGARY2008ttl!AN10/HUNGARY2008ttl!$BE$40 -> 0.0063391856 | AO14: =HUNGARY2008ttl!AO10/HUNGARY2008ttl!$BE$41 -> 0.0056833744 | AP14: =HUNGARY2008ttl!AP10/HUNGARY2008ttl!$BE$42 -> 0.0032536678 | AQ14: =HUNGARY2008ttl!AQ10/HUNGARY2008ttl!$BE$43 -> 0.0016241838 | AR14: =HUNGARY2008ttl!AR10/HUNGARY2008ttl!$BE$44 -> 0.0040203132 | AS14: =HUNGARY2008ttl!AS10/HUNGARY2008ttl!$BE$45 -> 0.0041493776 | AT14: =HUNGARY2008ttl!AT10/HUNGARY2008ttl!$BE$46 -> 0
A15: TTL_C19 | B15: =HUNGARY2008ttl!B11/HUNGARY2008ttl!$BE$2 -> 0.032583262 | C15: =HUNGARY2008ttl!C11/HUNGARY2008ttl!$BE$3 -> 0.039538715 | D15: =HUNGARY2008ttl!D11/HUNGARY2008ttl!$BE$4 -> 0.031814611 | E15: =HUNGARY2008ttl!E11/HUNGARY2008ttl!$BE$5 -> 0.040919424 | F15: =HUNGARY2008ttl!F11/HUNGARY2008ttl!$BE$6 -> 0.032901834 | G15: =HUNGARY2008ttl!G11/HUNGARY2008ttl!$BE$7 -> 0.010551085 | H15: =HUNGARY2008ttl!H11/HUNGARY2008ttl!$BE$8 -> 0.006142396 | I15: =HUNGARY2008ttl!I11/HUNGARY2008ttl!$BE$9 -> 0.010473981 | J15: =HUNGARY2008ttl!J11/HUNGARY2008ttl!$BE$10 -> 0.0070375109 | K15: =HUNGARY2008ttl!K11/HUNGARY2008ttl!$BE$11 -> 0.093468632 | L15: =HUNGARY2008ttl!L11/HUNGARY2008ttl!$BE$12 -> 0.15726449 | M15: =HUNGARY2008ttl!M11/HUNGARY2008ttl!$BE$13 -> 0.010645848 | N15: =HUNGARY2008ttl!N11/HUNGARY2008ttl!$BE$14 -> 0.015912083 | O15: =HUNGARY2008ttl!O11/HUNGARY2008ttl!$BE$15 -> 0.029179244 | P15: =HUNGARY2008ttl!P11/HUNGARY2008ttl!$BE$16 -> 0.042240222 | Q15: =HUNGARY2008ttl!Q11/HUNGARY2008ttl!$BE$17 -> 0.005445033 | R15: =HUNGARY2008ttl!R11/HUNGARY2008ttl!$BE$18 -> 0.0026896039 | S15: =HUNGARY2008ttl!S11/HUNGARY2008ttl!$BE$19 -> 0.0062449785 | T15: =HUNGARY2008ttl!T11/HUNGARY2008ttl!$BE$20 -> 0.005705649 | U15: =HUNGARY2008ttl!U11/HUNGARY2008ttl!$BE$21 -> 0.0032330504 | V15: =HUNGARY2008ttl!V11/HUNGARY2008ttl!$BE$22 -> 0.0052070719 | W15: =HUNGARY2008ttl!W11/HUNGARY2008ttl!$BE$23 -> 0.0070502615 | X15: =HUNGARY2008ttl!X11/HUNGARY2008ttl!$BE$24 -> 0.03339353 | Y15: =HUNGARY2008ttl!Y11/HUNGARY2008ttl!$BE$25 -> 0.022293098 | Z15: =HUNGARY2008ttl!Z11/HUNGARY2008ttl!$BE$26 -> 0.021434607 | AA15: =HUNGARY2008ttl!AA11/HUNGARY2008ttl!$BE$27 -> 0.016825115 | AB15: =HUNGARY2008ttl!AB11/HUNGARY2008ttl!$BE$28 -> 0.11644801 | AC15: =HUNGARY2008ttl!AC11/HUNGARY2008ttl!$BE$29 -> 0.17902913 | AD15: =HUNGARY2008ttl!AD11/HUNGARY2008ttl!$BE$30 -> 0.19657258 | AE15: =HUNGARY2008ttl!AE11/HUNGARY2008ttl!$BE$31 -> 0.035453513 | AF15: =HUNGARY2008ttl!AF11/HUNGARY2008ttl!$BE$32 -> 0.0099859701 | AG15: =HUNGARY2008ttl!AG11/HUNGARY2008ttl!$BE$33 -> 0.0054725288 | AH15: =HUNGARY2008ttl!AH11/HUNGARY2008ttl!$BE$34 -> 0.0024395087 | AI15: =HUNGARY2008ttl!AI11/HUNGARY2008ttl!$BE$35 -> 0.0024969961 | AJ15: =HUNGARY2008ttl!AJ11/HUNGARY2008ttl!$BE$36 -> 0.0038773257 | AK15: =HUNGARY2008ttl!AK11/HUNGARY2008ttl!$BE$37 -> 0.0045612435 | AL15: =HUNGARY2008ttl!AL11/HUNGARY2008ttl!$BE$38 -> 0.0058736461 | AM15: =HUNGARY2008ttl!AM11/HUNGARY2008ttl!$BE$39 -> 0.0078468794 | AN15: =HUNGARY2008ttl!AN11/HUNGARY2008ttl!$BE$40 -> 0.012287063 | AO15: =HUNGARY2008ttl!AO11/HUNGARY2008ttl!$BE$41 -> 0.0057144991 | AP15: =HUNGARY2008ttl!AP11/HUNGARY2008ttl!$BE$42 -> 0.0048035968 | AQ15: =HUNGARY2008ttl!AQ11/HUNGARY2008ttl!$BE$43 -> 0.0082203586 | AR15: =HUNGARY2008ttl!AR11/HUNGARY2008ttl!$BE$44 -> 0.0097333898 | AS15: =HUNGARY2008ttl!AS11/HUNGARY2008ttl!$BE$45 -> 0.0076565896 | AT15: =HUNGARY2008ttl!AT11/HUNGARY2008ttl!$BE$46 -> 0
A16: TTL_C20 | B16: =HUNGARY2008ttl!B12/HUNGARY2008ttl!$BE$2 -> 0.054123204 | C16: =HUNGARY2008ttl!C12/HUNGARY2008ttl!$BE$3 -> 0.0016474465 | D16: =HUNGARY2008ttl!D12/HUNGARY2008ttl!$BE$4 -> 0.0047132757 | E16: =HUNGARY2008ttl!E12/HUNGARY2008ttl!$BE$5 -> 0.013387219 | F16: =HUNGARY2008ttl!F12/HUNGARY2008ttl!$BE$6 -> 0.01618123 | G16: =HUNGARY2008ttl!G12/HUNGARY2008ttl!$BE$7 -> 0.026405153 | H16: =HUNGARY2008ttl!H12/HUNGARY2008ttl!$BE$8 -> 0.026273314 | I16: =HUNGARY2008ttl!I12/HUNGARY2008ttl!$BE$9 -> 0.030096122 | J16: =HUNGARY2008ttl!J12/HUNGARY2008ttl!$BE$10 -> 0.021078861 | K16: =HUNGARY2008ttl!K12/HUNGARY2008ttl!$BE$11 -> 0.034850596 | L16: =HUNGARY2008ttl!L12/HUNGARY2008ttl!$BE$12 -> 0.16658427 | M16: =HUNGARY2008ttl!M12/HUNGARY2008ttl!$BE$13 -> 0.080567779 | N16: =HUNGARY2008ttl!N12/HUNGARY2008ttl!$BE$14 -> 0.18863641 | O16: =HUNGARY2008ttl!O12/HUNGARY2008ttl!$BE$15 -> 0.048272723 | P16: =HUNGARY2008ttl!P12/HUNGARY2008ttl!$BE$16 -> 0.0090859493 | Q16: =HUNGARY2008ttl!Q12/HUNGARY2008ttl!$BE$17 -> 0.0096108113 | R16: =HUNGARY2008ttl!R12/HUNGARY2008ttl!$BE$18 -> 0.0075273693 | S16: =HUNGARY2008ttl!S12/HUNGARY2008ttl!$BE$19 -> 0.036812505 | T16: =HUNGARY2008ttl!T12/HUNGARY2008ttl!$BE$20 -> 0.0088040809 | U16: =HUNGARY2008ttl!U12/HUNGARY2008ttl!$BE$21 -> 0.007653497 | V16: =HUNGARY2008ttl!V12/HUNGARY2008ttl!$BE$22 -> 0.0073867765 | W16: =HUNGARY2008ttl!W12/HUNGARY2008ttl!$BE$23 -> 0.017312941 | X16: =HUNGARY2008ttl!X12/HUNGARY2008ttl!$BE$24 -> 0.0070357109 | Y16: =HUNGARY2008ttl!Y12/HUNGARY2008ttl!$BE$25 -> 0.01022589 | Z16: =HUNGARY2008ttl!Z12/HUNGARY2008ttl!$BE$26 -> 0.010806399 | AA16: =HUNGARY2008ttl!AA12/HUNGARY2008ttl!$BE$27 -> 0.007498548 | AB16: =HUNGARY2008ttl!AB12/HUNGARY2008ttl!$BE$28 -> 0.0038269767 | AC16: =HUNGARY2008ttl!AC12/HUNGARY2008ttl!$BE$29 -> 0.0081553398 | AD16: =HUNGARY2008ttl!AD12/HUNGARY2008ttl!$BE$30 -> 0.0032568238 | AE16: =HUNGARY2008ttl!AE12/HUNGARY2008ttl!$BE$31 -> 0.0028800909 | AF16: =HUNGARY2008ttl!AF12/HUNGARY2008ttl!$BE$32 -> 0.002310803 | AG16: =HUNGARY2008ttl!AG12/HUNGARY2008ttl!$BE$33 -> 0.0051934764 | AH16: =HUNGARY2008ttl!AH12/HUNGARY2008ttl!$BE$34 -> 0.0028650044 | AI16: =HUNGARY2008ttl!AI12/HUNGARY2008ttl!$BE$35 -> 0.00045058576 | AJ16: =HUNGARY2008ttl!AJ12/HUNGARY2008ttl!$BE$36 -> 0.0012385902 | AK16: =HUNGARY2008ttl!AK12/HUNGARY2008ttl!$BE$37 -> 0.001254342 | AL16: =HUNGARY2008ttl!AL12/HUNGARY2008ttl!$BE$38 -> 0.003900101 | AM16: =HUNGARY2008ttl!AM12/HUNGARY2008ttl!$BE$39 -> 0.0057885522 | AN16: =HUNGARY2008ttl!AN12/HUNGARY2008ttl!$BE$40 -> 0.0076435447 | AO16: =HUNGARY2008ttl!AO12/HUNGARY2008ttl!$BE$41 -> 0.0014192874 | AP16: =HUNGARY2008ttl!AP12/HUNGARY2008ttl!$BE$42 -> 0.0031945102 | AQ16: =HUNGARY2008ttl!AQ12/HUNGARY2008ttl!$BE$43 -> 0.0185621 | AR16: =HUNGARY2008ttl!AR12/HUNGARY2008ttl!$BE$44 -> 0.0097938456 | AS16: =HUNGARY2008ttl!AS12/HUNGARY2008ttl!$BE$45 -> 0.011065007 | AT16: =HUNGARY2008ttl!AT12/HUNGARY2008ttl!$BE$46 -> 0
A17: TTL_C21 | B17: =HUNGARY2008ttl!B13/HUNGARY2008ttl!$BE$2 -> 0.0039872583 | C17: =HUNGARY2008ttl!C13/HUNGARY2008ttl!$BE$3 -> 0.0016474465 | D17: =HUNGARY2008ttl!D13/HUNGARY2008ttl!$BE$4 -> 0.00078554595 | E17: =HUNGARY2008ttl!E13/HUNGARY2008ttl!$BE$5 -> 0.00075776711 | F17: =HUNGARY2008ttl!F13/HUNGARY2008ttl!$BE$6 -> 0.0010787487 | G17: =HUNGARY2008ttl!G13/HUNGARY2008ttl!$BE$7 -> 0.0026137603 | H17: =HUNGARY2008ttl!H13/HUNGARY2008ttl!$BE$8 -> 0.0018382353 | I17: =HUNGARY2008ttl!I13/HUNGARY2008ttl!$BE$9 -> 0.0014584024 | J17: =HUNGARY2008ttl!J13/HUNGARY2008ttl!$BE$10 -> 0.0011785305 | K17: =HUNGARY2008ttl!K13/HUNGARY2008ttl!$BE$11 -> 0.0013931921 | L17: =HUNGARY2008ttl!L13/HUNGARY2008ttl!$BE$12 -> 0.0065366658 | M17: =HUNGARY2008ttl!M13/HUNGARY2008ttl!$BE$13 -> 0.064755145 | N17: =HUNGARY2008ttl!N13/HUNGARY2008ttl!$BE$14 -> 0.0068876042 | O17: =HUNGARY2008ttl!O13/HUNGARY2008ttl!$BE$15 -> 0.001988405 | P17: =HUNGARY2008ttl!P13/HUNGARY2008ttl!$BE$16 -> 0.0017836159 | Q17: =HUNGARY2008ttl!Q13/HUNGARY2008ttl!$BE$17 -> 0.00067242878 | R17: =HUNGARY2008ttl!R13/HUNGARY2008ttl!$BE$18 -> 0.0010784827 | S17: =HUNGARY2008ttl!S13/HUNGARY2008ttl!$BE$19 -> 0.0019355781 | T17: =HUNGARY2008ttl!T13/HUNGARY2008ttl!$BE$20 -> 0.0008312866 | U17: =HUNGARY2008ttl!U13/HUNGARY2008ttl!$BE$21 -> 0.0011540657 | V17: =HUNGARY2008ttl!V13/HUNGARY2008ttl!$BE$22 -> 0.00060547348 | W17: =HUNGARY2008ttl!W13/HUNGARY2008ttl!$BE$23 -> 0.0012224244 | X17: =HUNGARY2008ttl!X13/HUNGARY2008ttl!$BE$24 -> 0.00057413071 | Y17: =HUNGARY2008ttl!Y13/HUNGARY2008ttl!$BE$25 -> 0.00065761352 | Z17: =HUNGARY2008ttl!Z13/HUNGARY2008ttl!$BE$26 -> 0.00080473182 | AA17: =HUNGARY2008ttl!AA13/HUNGARY2008ttl!$BE$27 -> 0.0008926115 | AB17: =HUNGARY2008ttl!AB13/HUNGARY2008ttl!$BE$28 -> 0.00049960531 | AC17: =HUNGARY2008ttl!AC13/HUNGARY2008ttl!$BE$29 -> 0.0015533981 | AD17: =HUNGARY2008ttl!AD13/HUNGARY2008ttl!$BE$30 -> 0.0010856079 | AE17: =HUNGARY2008ttl!AE13/HUNGARY2008ttl!$BE$31 -> 0.00036508194 | AF17: =HUNGARY2008ttl!AF13/HUNGARY2008ttl!$BE$32 -> 0.00024758604 | AG17: =HUNGARY2008ttl!AG13/HUNGARY2008ttl!$BE$33 -> 0.0007441399 | AH17: =HUNGARY2008ttl!AH13/HUNGARY2008ttl!$BE$34 -> 0.00051059484 | AI17: =HUNGARY2008ttl!AI13/HUNGARY2008ttl!$BE$35 -> 0.0002816161 | AJ17: =HUNGARY2008ttl!AJ13/HUNGARY2008ttl!$BE$36 -> 0.00053851746 | AK17: =HUNGARY2008ttl!AK13/HUNGARY2008ttl!$BE$37 -> 0.00028946353 | AL17: =HUNGARY2008ttl!AL13/HUNGARY2008ttl!$BE$38 -> 0.00036416606 | AM17: =HUNGARY2008ttl!AM13/HUNGARY2008ttl!$BE$39 -> 0.0012460371 | AN17: =HUNGARY2008ttl!AN13/HUNGARY2008ttl!$BE$40 -> 0.00080870268 | AO17: =HUNGARY2008ttl!AO13/HUNGARY2008ttl!$BE$41 -> 0.00035482184 | AP17: =HUNGARY2008ttl!AP13/HUNGARY2008ttl!$BE$42 -> 0.00035494558 | AQ17: =HUNGARY2008ttl!AQ13/HUNGARY2008ttl!$BE$43 -> 0.043709326 | AR17: =HUNGARY2008ttl!AR13/HUNGARY2008ttl!$BE$44 -> 0.0014509401 | AS17: =HUNGARY2008ttl!AS13/HUNGARY2008ttl!$BE$45 -> 0.0011608378 | AT17: =HUNGARY2008ttl!AT13/HUNGARY2008ttl!$BE$46 -> 0
... A50: TTL_T | B50: =HUNGARY2008ttl!B46/HUNGARY2008ttl!$BE$2 -> 0 | C50: =HUNGARY2008ttl!C46/HUNGARY2008ttl!$BE$3 -> 0 | D50: =HUNGARY2008ttl!D46/HUNGARY2008ttl!$BE$4 -> 0 | E50: =HUNGARY2008ttl!E46/HUNGARY2008ttl!$BE$5 -> 0 | F50: =HUNGARY2008ttl!F46/HUNGARY2008ttl!$BE$6 -> 0 | G50: =HUNGARY2008ttl!G46/HUNGARY2008ttl!$BE$7 -> 0 | H50: =HUNGARY2008ttl!H46/HUNGARY2008ttl!$BE$8 -> 0 | I50: =HUNGARY2008ttl!I46/HUNGARY2008ttl!$BE$9 -> 0 | J50: =HUNGARY2008ttl!J46/HUNGARY2008ttl!$BE$10 -> 0 | K50: =HUNGARY2008ttl!K46/HUNGARY2008ttl!$BE$11 -> 0 | L50: =HUNGARY2008ttl!L46/HUNGARY2008ttl!$BE$12 -> 0 | M50: =HUNGARY2008ttl!M46/HUNGARY2008ttl!$BE$13 -> 0 | N50: =HUNGARY2008ttl!N46/HUNGARY2008ttl!$BE$14 -> 0 | O50: =HUNGARY2008ttl!O46/HUNGARY2008ttl!$BE$15 -> 0 | P50: =HUNGARY2008ttl!P46/HUNGARY2008ttl!$BE$16 -> 0 | Q50: =HUNGARY2008ttl!Q46/HUNGARY2008ttl!$BE$17 -> 0 | R50: =HUNGARY2008ttl!R46/HUNGARY2008ttl!$BE$18 -> 0 | S50: =HUNGARY2008ttl!S46/HUNGARY2008ttl!$BE$19 -> 0 | T50: =HUNGARY2008ttl!T46/HUNGARY2008ttl!$BE$20 -> 0 | U50: =HUNGARY2008ttl!U46/HUNGARY2008ttl!$BE$21 -> 0 | V50: =HUNGARY2008ttl!V46/HUNGARY2008ttl!$BE$22 -> 0 | W50: =HUNGARY2008ttl!W46/HUNGARY2008ttl!$BE$23 -> 0 | X50: =HUNGARY2008ttl!X46/HUNGARY2008ttl!$BE$24 -> 0 | Y50: =HUNGARY2008ttl!Y46/HUNGARY2008ttl!$BE$25 -> 0 | Z50: =HUNGARY2008ttl!Z46/HUNGARY2008ttl!$BE$26 -> 0 | AA50: =HUNGARY2008ttl!AA46/HUNGARY2008ttl!$BE$27 -> 0 | AB50: =HUNGARY2008ttl!AB46/HUNGARY2008ttl!$BE$28 -> 0 | AC50: =HUNGARY2008ttl!AC46/HUNGARY2008ttl!$BE$29 -> 0 | AD50: =HUNGARY2008ttl!AD46/HUNGARY2008ttl!$BE$30 -> 0 | AE50: =HUNGARY2008ttl!AE46/HUNGARY2008ttl!$BE$31 -> 0 | AF50: =HUNGARY2008ttl!AF46/HUNGARY2008ttl!$BE$32 -> 0 | AG50: =HUNGARY2008ttl!AG46/HUNGARY2008ttl!$BE$33 -> 0 | AH50: =HUNGARY2008ttl!AH46/HUNGARY2008ttl!$BE$34 -> 0 | AI50: =HUNGARY2008ttl!AI46/HUNGARY2008ttl!$BE$35 -> 0 | AJ50: =HUNGARY2008ttl!AJ46/HUNGARY2008ttl!$BE$36 -> 0 | AK50: =HUNGARY2008ttl!AK46/HUNGARY2008ttl!$BE$37 -> 0 | AL50: =HUNGARY2008ttl!AL46/HUNGARY2008ttl!$BE$38 -> 0 | AM50: =HUNGARY2008ttl!AM46/HUNGARY2008ttl!$BE$39 -> 0 | AN50: =HUNGARY2008ttl!AN46/HUNGARY2008ttl!$BE$40 -> 0 | AO50: =HUNGARY2008ttl!AO46/HUNGARY2008ttl!$BE$41 -> 0 | AP50: =HUNGARY2008ttl!AP46/HUNGARY2008ttl!$BE$42 -> 0 | AQ50: =HUNGARY2008ttl!AQ46/HUNGARY2008ttl!$BE$43 -> 0 | AR50: =HUNGARY2008ttl!AR46/HUNGARY2008ttl!$BE$44 -> 0 | AS50: =HUNGARY2008ttl!AS46/HUNGARY2008ttl!$BE$45 -> 0 | AT50: =HUNGARY2008ttl!AT46/HUNGARY2008ttl!$BE$46 -> 0
B53: IDENTITY MATRIX(I)
B57: 1 | C57: 0 | D57: 0 | E57: 0 | F57: 0 | G57: 0 | H57: 0 | I57: 0 | J57: 0 | K57: 0 | L57: 0 | M57: 0 | N57: 0 | O57: 0 | P57: 0 | Q57: 0 | R57: 0 | S57: 0 | T57: 0 | U57: 0 | V57: 0 | W57: 0 | X57: 0 | Y57: 0 | Z57: 0 | AA57: 0 | AB57: 0 | AC57: 0 | AD57: 0 | AE57: 0 | AF57: 0 | AG57: 0 | AH57: 0 | AI57: 0 | AJ57: 0 | AK57: 0 | AL57: 0 | AM57: 0 | AN57: 0 | AO57: 0 | AP57: 0 | AQ57: 0 | AR57: 0 | AS57: 0 | AT57: 0
B58: 0 | C58: 1 | D58: 0 | E58: 0 | F58: 0 | G58: 0 | H58: 0 | I58: 0 | J58: 0 | K58: 0 | L58: 0 | M58: 0 | N58: 0 | O58: 0 | P58: 0 | Q58: 0 | R58: 0 | S58: 0 | T58: 0 | U58: 0 | V58: 0 | W58: 0 | X58: 0 | Y58: 0 | Z58: 0 | AA58: 0 | AB58: 0 | AC58: 0 | AD58: 0 | AE58: 0 | AF58: 0 | AG58: 0 | AH58: 0 | AI58: 0 | AJ58: 0 | AK58: 0 | AL58: 0 | AM58: 0 | AN58: 0 | AO58: 0 | AP58: 0 | AQ58: 0 | AR58: 0 | AS58: 0 | AT58: 0
B59: 0 | C59: 0 | D59: 1 | E59: 0 | F59: 0 | G59: 0 | H59: 0 | I59: 0 | J59: 0 | K59: 0 | L59: 0 | M59: 0 | N59: 0 | O59: 0 | P59: 0 | Q59: 0 | R59: 0 | S59: 0 | T59: 0 | U59: 0 | V59: 0 | W59: 0 | X59: 0 | Y59: 0 | Z59: 0 | AA59: 0 | AB59: 0 | AC59: 0 | AD59: 0 | AE59: 0 | AF59: 0 | AG59: 0 | AH59: 0 | AI59: 0 | AJ59: 0 | AK59: 0 | AL59: 0 | AM59: 0 | AN59: 0 | AO59: 0 | AP59: 0 | AQ59: 0 | AR59: 0 | AS59: 0 | AT59: 0
B60: 0 | C60: 0 | D60: 0 | E60: 1 | F60: 0 | G60: 0 | H60: 0 | I60: 0 | J60: 0 | K60: 0 | L60: 0 | M60: 0 | N60: 0 | O60: 0 | P60: 0 | Q60: 0 | R60: 0 | S60: 0 | T60: 0 | U60: 0 | V60: 0 | W60: 0 | X60: 0 | Y60: 0 | Z60: 0 | AA60: 0 | AB60: 0 | AC60: 0 | AD60: 0 | AE60: 0 | AF60: 0 | AG60: 0 | AH60: 0 | AI60: 0 | AJ60: 0 | AK60: 0 | AL60: 0 | AM60: 0 | AN60: 0 | AO60: 0 | AP60: 0 | AQ60: 0 | AR60: 0 | AS60: 0 | AT60: 0
B61: 0 | C61: 0 | D61: 0 | E61: 0 | F61: 1 | G61: 0 | H61: 0 | I61: 0 | J61: 0 | K61: 0 | L61: 0 | M61: 0 | N61: 0 | O61: 0 | P61: 0 | Q61: 0 | R61: 0 | S61: 0 | T61: 0 | U61: 0 | V61: 0 | W61: 0 | X61: 0 | Y61: 0 | Z61: 0 | AA61: 0 | AB61: 0 | AC61: 0 | AD61: 0 | AE61: 0 | AF61: 0 | AG61: 0 | AH61: 0 | AI61: 0 | AJ61: 0 | AK61: 0 | AL61: 0 | AM61: 0 | AN61: 0 | AO61: 0 | AP61: 0 | AQ61: 0 | AR61: 0 | AS61: 0 | AT61: 0
B62: 0 | C62: 0 | D62: 0 | E62: 0 | F62: 0 | G62: 1 | H62: 0 | I62: 0 | J62: 0 | K62: 0 | L62: 0 | M62: 0 | N62: 0 | O62: 0 | P62: 0 | Q62: 0 | R62: 0 | S62: 0 | T62: 0 | U62: 0 | V62: 0 | W62: 0 | X62: 0 | Y62: 0 | Z62: 0 | AA62: 0 | AB62: 0 | AC62: 0 | AD62: 0 | AE62: 0 | AF62: 0 | AG62: 0 | AH62: 0 | AI62: 0 | AJ62: 0 | AK62: 0 | AL62: 0 | AM62: 0 | AN62: 0 | AO62: 0 | AP62: 0 | AQ62: 0 | AR62: 0 | AS62: 0 | AT62: 0
B63: 0 | C63: 0 | D63: 0 | E63: 0 | F63: 0 | G63: 0 | H63: 1 | I63: 0 | J63: 0 | K63: 0 | L63: 0 | M63: 0 | N63: 0 | O63: 0 | P63: 0 | Q63: 0 | R63: 0 | S63: 0 | T63: 0 | U63: 0 | V63: 0 | W63: 0 | X63: 0 | Y63: 0 | Z63: 0 | AA63: 0 | AB63: 0 | AC63: 0 | AD63: 0 | AE63: 0 | AF63: 0 | AG63: 0 | AH63: 0 | AI63: 0 | AJ63: 0 | AK63: 0 | AL63: 0 | AM63: 0 | AN63: 0 | AO63: 0 | AP63: 0 | AQ63: 0 | AR63: 0 | AS63: 0 | AT63: 0
B64: 0 | C64: 0 | D64: 0 | E64: 0 | F64: 0 | G64: 0 | H64: 0 | I64: 1 | J64: 0 | K64: 0 | L64: 0 | M64: 0 | N64: 0 | O64: 0 | P64: 0 | Q64: 0 | R64: 0 | S64: 0 | T64: 0 | U64: 0 | V64: 0 | W64: 0 | X64: 0 | Y64: 0 | Z64: 0 | AA64: 0 | AB64: 0 | AC64: 0 | AD64: 0 | AE64: 0 | AF64: 0 | AG64: 0 | AH64: 0 | AI64: 0 | AJ64: 0 | AK64: 0 | AL64: 0 | AM64: 0 | AN64: 0 | AO64: 0 | AP64: 0 | AQ64: 0 | AR64: 0 | AS64: 0 | AT64: 0
